[2024-09-12T22:36:43.645+0000] {local_task_job_runner.py:120} INFO - ::group::Pre task execution logs
[2024-09-12T22:36:43.655+0000] {taskinstance.py:2076} INFO - Dependencies all met for dep_context=non-requeueable deps ti=<TaskInstance: example_python_operator_hook.call_api_task manual__2024-09-12T22:36:42.443212+00:00 [queued]>
[2024-09-12T22:36:43.661+0000] {taskinstance.py:2076} INFO - Dependencies all met for dep_context=requeueable deps ti=<TaskInstance: example_python_operator_hook.call_api_task manual__2024-09-12T22:36:42.443212+00:00 [queued]>
[2024-09-12T22:36:43.661+0000] {taskinstance.py:2306} INFO - Starting attempt 1 of 2
[2024-09-12T22:36:43.671+0000] {taskinstance.py:2330} INFO - Executing <Task(PythonOperator): call_api_task> on 2024-09-12 22:36:42.443212+00:00
[2024-09-12T22:36:43.677+0000] {logging_mixin.py:188} WARNING - /home/***/.local/lib/python3.12/site-packages/***/task/task_runner/standard_task_runner.py:61 DeprecationWarning: This process (pid=2250) is multi-threaded, use of fork() may lead to deadlocks in the child.
[2024-09-12T22:36:43.678+0000] {standard_task_runner.py:63} INFO - Started process 2252 to run task
[2024-09-12T22:36:43.678+0000] {standard_task_runner.py:90} INFO - Running: ['***', 'tasks', 'run', 'example_python_operator_hook', 'call_api_task', 'manual__2024-09-12T22:36:42.443212+00:00', '--job-id', '107', '--raw', '--subdir', 'DAGS_FOLDER/example_python_operator_hook.py', '--cfg-path', '/tmp/tmpk1ibcbq9']
[2024-09-12T22:36:43.679+0000] {standard_task_runner.py:91} INFO - Job 107: Subtask call_api_task
[2024-09-12T22:36:43.709+0000] {task_command.py:426} INFO - Running <TaskInstance: example_python_operator_hook.call_api_task manual__2024-09-12T22:36:42.443212+00:00 [running]> on host 1ab47b72986b
[2024-09-12T22:36:43.772+0000] {taskinstance.py:2648} INFO - Exporting env vars: AIRFLOW_CTX_DAG_OWNER='***' AIRFLOW_CTX_DAG_ID='example_python_operator_hook' AIRFLOW_CTX_TASK_ID='call_api_task' AIRFLOW_CTX_EXECUTION_DATE='2024-09-12T22:36:42.443212+00:00' AIRFLOW_CTX_TRY_NUMBER='1' AIRFLOW_CTX_DAG_RUN_ID='manual__2024-09-12T22:36:42.443212+00:00'
[2024-09-12T22:36:43.773+0000] {taskinstance.py:430} INFO - ::endgroup::
[2024-09-12T22:36:43.789+0000] {base.py:84} INFO - Using connection ID 'ingestion_api' for task execution.
[2024-09-12T22:36:43.974+0000] {logging_mixin.py:188} INFO - DataFrame saved to PostgreSQL successfully.
[2024-09-12T22:36:43.992+0000] {_metadata.py:139} WARNING - Compute Engine Metadata server unavailable on attempt 1 of 3. Reason: [Errno 111] Connection refused
[2024-09-12T22:36:43.993+0000] {_metadata.py:139} WARNING - Compute Engine Metadata server unavailable on attempt 2 of 3. Reason: [Errno 111] Connection refused
[2024-09-12T22:36:43.994+0000] {_metadata.py:139} WARNING - Compute Engine Metadata server unavailable on attempt 3 of 3. Reason: [Errno 111] Connection refused
[2024-09-12T22:36:43.994+0000] {_default.py:338} WARNING - Authentication failed using Compute Engine authentication due to unavailable metadata server.
[2024-09-12T22:36:43.996+0000] {taskinstance.py:441} INFO - ::group::Post task execution logs
[2024-09-12T22:36:43.996+0000] {taskinstance.py:2905} ERROR - Task failed with exception
Traceback (most recent call last):
  File "/home/airflow/.local/lib/python3.12/site-packages/airflow/models/taskinstance.py", line 465, in _execute_task
    result = _execute_callable(context=context, **execute_callable_kwargs)
             ^^^^^^^^^^^^^^^^^^^^^^^^^^^^^^^^^^^^^^^^^^^^^^^^^^^^^^^^^^^^^
  File "/home/airflow/.local/lib/python3.12/site-packages/airflow/models/taskinstance.py", line 432, in _execute_callable
    return execute_callable(context=context, **execute_callable_kwargs)
           ^^^^^^^^^^^^^^^^^^^^^^^^^^^^^^^^^^^^^^^^^^^^^^^^^^^^^^^^^^^^
  File "/home/airflow/.local/lib/python3.12/site-packages/airflow/models/baseoperator.py", line 400, in wrapper
    return func(self, *args, **kwargs)
           ^^^^^^^^^^^^^^^^^^^^^^^^^^^
  File "/home/airflow/.local/lib/python3.12/site-packages/airflow/operators/python.py", line 235, in execute
    return_value = self.execute_callable()
                   ^^^^^^^^^^^^^^^^^^^^^^^
  File "/home/airflow/.local/lib/python3.12/site-packages/airflow/operators/python.py", line 252, in execute_callable
    return self.python_callable(*self.op_args, **self.op_kwargs)
           ^^^^^^^^^^^^^^^^^^^^^^^^^^^^^^^^^^^^^^^^^^^^^^^^^^^^^
  File "/opt/airflow/dags/example_python_operator_hook.py", line 43, in call_api
    upload_to_bigquery(df)
  File "/opt/airflow/dags/example_python_operator_hook.py", line 53, in upload_to_bigquery
    to_gbq(df, table_id, project_id=BIGQUERY_PROJECT_ID, if_exists='replace')
  File "/home/airflow/.local/lib/python3.12/site-packages/pandas_gbq/gbq.py", line 1076, in to_gbq
    connector = GbqConnector(
                ^^^^^^^^^^^^^
  File "/home/airflow/.local/lib/python3.12/site-packages/pandas_gbq/gbq.py", line 299, in __init__
    self.credentials, default_project = auth.get_credentials(
                                        ^^^^^^^^^^^^^^^^^^^^^
  File "/home/airflow/.local/lib/python3.12/site-packages/pandas_gbq/auth.py", line 56, in get_credentials
    credentials, default_project_id = pydata_google_auth.default(
                                      ^^^^^^^^^^^^^^^^^^^^^^^^^^^
  File "/home/airflow/.local/lib/python3.12/site-packages/pydata_google_auth/auth.py", line 152, in default
    credentials = get_user_credentials(
                  ^^^^^^^^^^^^^^^^^^^^^
  File "/home/airflow/.local/lib/python3.12/site-packages/pydata_google_auth/auth.py", line 362, in get_user_credentials
    credentials = _webserver.run_local_server(app_flow, **AUTH_URI_KWARGS)
                  ^^^^^^^^^^^^^^^^^^^^^^^^^^^^^^^^^^^^^^^^^^^^^^^^^^^^^^^^
  File "/home/airflow/.local/lib/python3.12/site-packages/pydata_google_auth/_webserver.py", line 89, in run_local_server
    return app_flow.run_local_server(host=LOCALHOST, port=port, **kwargs)
           ^^^^^^^^^^^^^^^^^^^^^^^^^^^^^^^^^^^^^^^^^^^^^^^^^^^^^^^^^^^^^^
  File "/home/airflow/.local/lib/python3.12/site-packages/google_auth_oauthlib/flow.py", line 444, in run_local_server
    webbrowser.get(browser).open(auth_url, new=1, autoraise=True)
    ^^^^^^^^^^^^^^^^^^^^^^^
  File "/usr/local/lib/python3.12/webbrowser.py", line 66, in get
    raise Error("could not locate runnable browser")
webbrowser.Error: could not locate runnable browser
[2024-09-12T22:36:44.005+0000] {taskinstance.py:1206} INFO - Marking task as UP_FOR_RETRY. dag_id=example_python_operator_hook, task_id=call_api_task, run_id=manual__2024-09-12T22:36:42.443212+00:00, execution_date=20240912T223642, start_date=20240912T223643, end_date=20240912T223644
[2024-09-12T22:36:44.014+0000] {standard_task_runner.py:110} ERROR - Failed to execute job 107 for task call_api_task (could not locate runnable browser; 2252)
[2024-09-12T22:36:44.051+0000] {local_task_job_runner.py:240} INFO - Task exited with return code 1
[2024-09-12T22:36:44.062+0000] {taskinstance.py:3498} INFO - 0 downstream tasks scheduled from follow-on schedule check
[2024-09-12T22:36:44.064+0000] {local_task_job_runner.py:222} INFO - ::endgroup::
