[2024-09-12T21:43:33.994+0000] {local_task_job_runner.py:120} INFO - ::group::Pre task execution logs
[2024-09-12T21:43:34.005+0000] {taskinstance.py:2076} INFO - Dependencies all met for dep_context=non-requeueable deps ti=<TaskInstance: example_python_operator_hook.call_api_task manual__2024-09-12T21:43:33.119183+00:00 [queued]>
[2024-09-12T21:43:34.011+0000] {taskinstance.py:2076} INFO - Dependencies all met for dep_context=requeueable deps ti=<TaskInstance: example_python_operator_hook.call_api_task manual__2024-09-12T21:43:33.119183+00:00 [queued]>
[2024-09-12T21:43:34.011+0000] {taskinstance.py:2306} INFO - Starting attempt 1 of 2
[2024-09-12T21:43:34.021+0000] {taskinstance.py:2330} INFO - Executing <Task(PythonOperator): call_api_task> on 2024-09-12 21:43:33.119183+00:00
[2024-09-12T21:43:34.027+0000] {standard_task_runner.py:90} INFO - Running: ['***', 'tasks', 'run', 'example_python_operator_hook', 'call_api_task', 'manual__2024-09-12T21:43:33.119183+00:00', '--job-id', '65', '--raw', '--subdir', 'DAGS_FOLDER/example_python_operator_hook.py', '--cfg-path', '/tmp/tmpj637p8g8']
[2024-09-12T21:43:34.028+0000] {standard_task_runner.py:91} INFO - Job 65: Subtask call_api_task
[2024-09-12T21:43:34.030+0000] {logging_mixin.py:188} WARNING - /home/***/.local/lib/python3.12/site-packages/***/task/task_runner/standard_task_runner.py:61 DeprecationWarning: This process (pid=792) is multi-threaded, use of fork() may lead to deadlocks in the child.
[2024-09-12T21:43:34.031+0000] {standard_task_runner.py:63} INFO - Started process 794 to run task
[2024-09-12T21:43:34.056+0000] {task_command.py:426} INFO - Running <TaskInstance: example_python_operator_hook.call_api_task manual__2024-09-12T21:43:33.119183+00:00 [running]> on host 1ab47b72986b
[2024-09-12T21:43:34.120+0000] {taskinstance.py:2648} INFO - Exporting env vars: AIRFLOW_CTX_DAG_OWNER='***' AIRFLOW_CTX_DAG_ID='example_python_operator_hook' AIRFLOW_CTX_TASK_ID='call_api_task' AIRFLOW_CTX_EXECUTION_DATE='2024-09-12T21:43:33.119183+00:00' AIRFLOW_CTX_TRY_NUMBER='1' AIRFLOW_CTX_DAG_RUN_ID='manual__2024-09-12T21:43:33.119183+00:00'
[2024-09-12T21:43:34.121+0000] {taskinstance.py:430} INFO - ::endgroup::
[2024-09-12T21:43:34.137+0000] {base.py:84} INFO - Using connection ID 'ingestion_api' for task execution.
[2024-09-12T21:43:34.372+0000] {logging_mixin.py:188} INFO - DataFrame saved to PostgreSQL successfully.
[2024-09-12T21:43:34.373+0000] {taskinstance.py:441} INFO - ::group::Post task execution logs
[2024-09-12T21:43:34.373+0000] {taskinstance.py:2905} ERROR - Task failed with exception
Traceback (most recent call last):
  File "/home/airflow/.local/lib/python3.12/site-packages/airflow/models/taskinstance.py", line 465, in _execute_task
    result = _execute_callable(context=context, **execute_callable_kwargs)
             ^^^^^^^^^^^^^^^^^^^^^^^^^^^^^^^^^^^^^^^^^^^^^^^^^^^^^^^^^^^^^
  File "/home/airflow/.local/lib/python3.12/site-packages/airflow/models/taskinstance.py", line 432, in _execute_callable
    return execute_callable(context=context, **execute_callable_kwargs)
           ^^^^^^^^^^^^^^^^^^^^^^^^^^^^^^^^^^^^^^^^^^^^^^^^^^^^^^^^^^^^
  File "/home/airflow/.local/lib/python3.12/site-packages/airflow/models/baseoperator.py", line 400, in wrapper
    return func(self, *args, **kwargs)
           ^^^^^^^^^^^^^^^^^^^^^^^^^^^
  File "/home/airflow/.local/lib/python3.12/site-packages/airflow/operators/python.py", line 235, in execute
    return_value = self.execute_callable()
                   ^^^^^^^^^^^^^^^^^^^^^^^
  File "/home/airflow/.local/lib/python3.12/site-packages/airflow/operators/python.py", line 252, in execute_callable
    return self.python_callable(*self.op_args, **self.op_kwargs)
           ^^^^^^^^^^^^^^^^^^^^^^^^^^^^^^^^^^^^^^^^^^^^^^^^^^^^^
  File "/opt/airflow/dags/example_python_operator_hook.py", line 40, in call_api
    upload_to_gcs(df)
  File "/opt/airflow/dags/example_python_operator_hook.py", line 47, in upload_to_gcs
    client = storage.Client.from_service_account_json(r'C:\Users\diana\Desktop\new_test\service-account-file.json')
             ^^^^^^^^^^^^^^^^^^^^^^^^^^^^^^^^^^^^^^^^^^^^^^^^^^^^^^^^^^^^^^^^^^^^^^^^^^^^^^^^^^^^^^^^^^^^^^^^^^^^^^
  File "/home/airflow/.local/lib/python3.12/site-packages/google/cloud/client/__init__.py", line 106, in from_service_account_json
    with io.open(json_credentials_path, "r", encoding="utf-8") as json_fi:
         ^^^^^^^^^^^^^^^^^^^^^^^^^^^^^^^^^^^^^^^^^^^^^^^^^^^^^
FileNotFoundError: [Errno 2] No such file or directory: 'C:\\Users\\diana\\Desktop\\new_test\\service-account-file.json'
[2024-09-12T21:43:34.382+0000] {taskinstance.py:1206} INFO - Marking task as UP_FOR_RETRY. dag_id=example_python_operator_hook, task_id=call_api_task, run_id=manual__2024-09-12T21:43:33.119183+00:00, execution_date=20240912T214333, start_date=20240912T214334, end_date=20240912T214334
[2024-09-12T21:43:34.391+0000] {standard_task_runner.py:110} ERROR - Failed to execute job 65 for task call_api_task ([Errno 2] No such file or directory: 'C:\\Users\\diana\\Desktop\\new_test\\service-account-file.json'; 794)
[2024-09-12T21:43:34.404+0000] {local_task_job_runner.py:240} INFO - Task exited with return code 1
[2024-09-12T21:43:34.420+0000] {taskinstance.py:3498} INFO - 0 downstream tasks scheduled from follow-on schedule check
[2024-09-12T21:43:34.422+0000] {local_task_job_runner.py:222} INFO - ::endgroup::
