[2024-09-03T09:07:39.876+0000] {local_task_job_runner.py:123} INFO - ::group::Pre task execution logs
[2024-09-03T09:07:39.889+0000] {taskinstance.py:2603} INFO - Dependencies all met for dep_context=non-requeueable deps ti=<TaskInstance: weather_ingestion_dag.run_weather_script manual__2024-09-03T09:07:38.558881+00:00 [queued]>
[2024-09-03T09:07:39.894+0000] {taskinstance.py:2603} INFO - Dependencies all met for dep_context=requeueable deps ti=<TaskInstance: weather_ingestion_dag.run_weather_script manual__2024-09-03T09:07:38.558881+00:00 [queued]>
[2024-09-03T09:07:39.895+0000] {taskinstance.py:2856} INFO - Starting attempt 1 of 2
[2024-09-03T09:07:39.904+0000] {taskinstance.py:2879} INFO - Executing <Task(PythonOperator): run_weather_script> on 2024-09-03 09:07:38.558881+00:00
[2024-09-03T09:07:39.911+0000] {warnings.py:112} WARNING - /home/***/.local/lib/python3.12/site-packages/***/task/task_runner/standard_task_runner.py:70: DeprecationWarning: This process (pid=2646) is multi-threaded, use of fork() may lead to deadlocks in the child.
  pid = os.fork()

[2024-09-03T09:07:39.912+0000] {standard_task_runner.py:72} INFO - Started process 2655 to run task
[2024-09-03T09:07:39.912+0000] {standard_task_runner.py:104} INFO - Running: ['***', 'tasks', 'run', 'weather_ingestion_dag', 'run_weather_script', 'manual__2024-09-03T09:07:38.558881+00:00', '--job-id', '62', '--raw', '--subdir', 'DAGS_FOLDER/weather_dag.py', '--cfg-path', '/tmp/tmpv5hinsuv']
[2024-09-03T09:07:39.913+0000] {standard_task_runner.py:105} INFO - Job 62: Subtask run_weather_script
[2024-09-03T09:07:39.948+0000] {task_command.py:467} INFO - Running <TaskInstance: weather_ingestion_dag.run_weather_script manual__2024-09-03T09:07:38.558881+00:00 [running]> on host 670a75e9450f
[2024-09-03T09:07:40.008+0000] {taskinstance.py:3122} INFO - Exporting env vars: AIRFLOW_CTX_DAG_OWNER='***' AIRFLOW_CTX_DAG_ID='weather_ingestion_dag' AIRFLOW_CTX_TASK_ID='run_weather_script' AIRFLOW_CTX_EXECUTION_DATE='2024-09-03T09:07:38.558881+00:00' AIRFLOW_CTX_TRY_NUMBER='1' AIRFLOW_CTX_DAG_RUN_ID='manual__2024-09-03T09:07:38.558881+00:00'
[2024-09-03T09:07:40.009+0000] {logging_mixin.py:190} INFO - Task instance is in running state
[2024-09-03T09:07:40.010+0000] {logging_mixin.py:190} INFO -  Previous state of the Task instance: queued
[2024-09-03T09:07:40.010+0000] {logging_mixin.py:190} INFO - Current task name:run_weather_script state:running start_date:2024-09-03 09:07:39.889712+00:00
[2024-09-03T09:07:40.010+0000] {logging_mixin.py:190} INFO - Dag name:weather_ingestion_dag and current dag run status:running
[2024-09-03T09:07:40.011+0000] {taskinstance.py:731} INFO - ::endgroup::
[2024-09-03T09:07:40.039+0000] {logging_mixin.py:190} INFO - Error occurred: Command '['python', 'projekt_fetch2.py']' returned non-zero exit status 2.
[2024-09-03T09:07:40.039+0000] {logging_mixin.py:190} INFO - stdout: 
[2024-09-03T09:07:40.039+0000] {logging_mixin.py:190} INFO - stderr: python: can't open file '/opt/***/projekt_fetch2.py': [Errno 2] No such file or directory
[2024-09-03T09:07:40.040+0000] {taskinstance.py:3301} ERROR - Task failed with exception
Traceback (most recent call last):
  File "/home/airflow/.local/lib/python3.12/site-packages/airflow/models/taskinstance.py", line 767, in _execute_task
    result = _execute_callable(context=context, **execute_callable_kwargs)
             ^^^^^^^^^^^^^^^^^^^^^^^^^^^^^^^^^^^^^^^^^^^^^^^^^^^^^^^^^^^^^
  File "/home/airflow/.local/lib/python3.12/site-packages/airflow/models/taskinstance.py", line 733, in _execute_callable
    return ExecutionCallableRunner(
           ^^^^^^^^^^^^^^^^^^^^^^^^
  File "/home/airflow/.local/lib/python3.12/site-packages/airflow/utils/operator_helpers.py", line 252, in run
    return self.func(*args, **kwargs)
           ^^^^^^^^^^^^^^^^^^^^^^^^^^
  File "/home/airflow/.local/lib/python3.12/site-packages/airflow/models/baseoperator.py", line 406, in wrapper
    return func(self, *args, **kwargs)
           ^^^^^^^^^^^^^^^^^^^^^^^^^^^
  File "/home/airflow/.local/lib/python3.12/site-packages/airflow/operators/python.py", line 238, in execute
    return_value = self.execute_callable()
                   ^^^^^^^^^^^^^^^^^^^^^^^
  File "/home/airflow/.local/lib/python3.12/site-packages/airflow/operators/python.py", line 256, in execute_callable
    return runner.run(*self.op_args, **self.op_kwargs)
           ^^^^^^^^^^^^^^^^^^^^^^^^^^^^^^^^^^^^^^^^^^^
  File "/home/airflow/.local/lib/python3.12/site-packages/airflow/utils/operator_helpers.py", line 252, in run
    return self.func(*args, **kwargs)
           ^^^^^^^^^^^^^^^^^^^^^^^^^^
  File "/opt/airflow/dags/weather_dag.py", line 31, in run_python_script
    result = subprocess.run(['python', script_path], capture_output=True, text=True, check=True)
             ^^^^^^^^^^^^^^^^^^^^^^^^^^^^^^^^^^^^^^^^^^^^^^^^^^^^^^^^^^^^^^^^^^^^^^^^^^^^^^^^^^^
  File "/usr/local/lib/python3.12/subprocess.py", line 571, in run
    raise CalledProcessError(retcode, process.args,
subprocess.CalledProcessError: Command '['python', 'projekt_fetch2.py']' returned non-zero exit status 2.
[2024-09-03T09:07:40.051+0000] {logging_mixin.py:190} INFO - Task instance in failure state
[2024-09-03T09:07:40.051+0000] {logging_mixin.py:190} INFO - Task start:2024-09-03 09:07:39.889712+00:00 end:2024-09-03 09:07:40.051104+00:00 duration:0.161392
[2024-09-03T09:07:40.052+0000] {logging_mixin.py:190} INFO - Task:<Task(PythonOperator): run_weather_script> dag:<DAG: weather_ingestion_dag> dagrun:<DagRun weather_ingestion_dag @ 2024-09-03 09:07:38.558881+00:00: manual__2024-09-03T09:07:38.558881+00:00, state:running, queued_at: 2024-09-03 09:07:38.564943+00:00. externally triggered: True>
[2024-09-03T09:07:40.052+0000] {logging_mixin.py:190} INFO - Failure caused by Command '['python', 'projekt_fetch2.py']' returned non-zero exit status 2.
[2024-09-03T09:07:40.052+0000] {taskinstance.py:1225} INFO - Marking task as UP_FOR_RETRY. dag_id=weather_ingestion_dag, task_id=run_weather_script, run_id=manual__2024-09-03T09:07:38.558881+00:00, execution_date=20240903T090738, start_date=20240903T090739, end_date=20240903T090740
[2024-09-03T09:07:40.064+0000] {taskinstance.py:340} INFO - ::group::Post task execution logs
[2024-09-03T09:07:40.065+0000] {standard_task_runner.py:124} ERROR - Failed to execute job 62 for task run_weather_script (Command '['python', 'projekt_fetch2.py']' returned non-zero exit status 2.; 2655)
Traceback (most recent call last):
  File "/home/airflow/.local/lib/python3.12/site-packages/airflow/task/task_runner/standard_task_runner.py", line 117, in _start_by_fork
    ret = args.func(args, dag=self.dag)
          ^^^^^^^^^^^^^^^^^^^^^^^^^^^^^
  File "/home/airflow/.local/lib/python3.12/site-packages/airflow/cli/cli_config.py", line 49, in command
    return func(*args, **kwargs)
           ^^^^^^^^^^^^^^^^^^^^^
  File "/home/airflow/.local/lib/python3.12/site-packages/airflow/utils/cli.py", line 115, in wrapper
    return f(*args, **kwargs)
           ^^^^^^^^^^^^^^^^^^
  File "/home/airflow/.local/lib/python3.12/site-packages/airflow/cli/commands/task_command.py", line 483, in task_run
    task_return_code = _run_task_by_selected_method(args, _dag, ti)
                       ^^^^^^^^^^^^^^^^^^^^^^^^^^^^^^^^^^^^^^^^^^^^
  File "/home/airflow/.local/lib/python3.12/site-packages/airflow/cli/commands/task_command.py", line 256, in _run_task_by_selected_method
    return _run_raw_task(args, ti)
           ^^^^^^^^^^^^^^^^^^^^^^^
  File "/home/airflow/.local/lib/python3.12/site-packages/airflow/cli/commands/task_command.py", line 341, in _run_raw_task
    return ti._run_raw_task(
           ^^^^^^^^^^^^^^^^^
  File "/home/airflow/.local/lib/python3.12/site-packages/airflow/utils/session.py", line 97, in wrapper
    return func(*args, session=session, **kwargs)
           ^^^^^^^^^^^^^^^^^^^^^^^^^^^^^^^^^^^^^^
  File "/home/airflow/.local/lib/python3.12/site-packages/airflow/models/taskinstance.py", line 2995, in _run_raw_task
    return _run_raw_task(
           ^^^^^^^^^^^^^^
  File "/home/airflow/.local/lib/python3.12/site-packages/airflow/models/taskinstance.py", line 273, in _run_raw_task
    TaskInstance._execute_task_with_callbacks(
  File "/home/airflow/.local/lib/python3.12/site-packages/airflow/models/taskinstance.py", line 3149, in _execute_task_with_callbacks
    result = self._execute_task(context, task_orig)
             ^^^^^^^^^^^^^^^^^^^^^^^^^^^^^^^^^^^^^^
  File "/home/airflow/.local/lib/python3.12/site-packages/airflow/models/taskinstance.py", line 3173, in _execute_task
    return _execute_task(self, context, task_orig)
           ^^^^^^^^^^^^^^^^^^^^^^^^^^^^^^^^^^^^^^^
  File "/home/airflow/.local/lib/python3.12/site-packages/airflow/models/taskinstance.py", line 767, in _execute_task
    result = _execute_callable(context=context, **execute_callable_kwargs)
             ^^^^^^^^^^^^^^^^^^^^^^^^^^^^^^^^^^^^^^^^^^^^^^^^^^^^^^^^^^^^^
  File "/home/airflow/.local/lib/python3.12/site-packages/airflow/models/taskinstance.py", line 733, in _execute_callable
    return ExecutionCallableRunner(
           ^^^^^^^^^^^^^^^^^^^^^^^^
  File "/home/airflow/.local/lib/python3.12/site-packages/airflow/utils/operator_helpers.py", line 252, in run
    return self.func(*args, **kwargs)
           ^^^^^^^^^^^^^^^^^^^^^^^^^^
  File "/home/airflow/.local/lib/python3.12/site-packages/airflow/models/baseoperator.py", line 406, in wrapper
    return func(self, *args, **kwargs)
           ^^^^^^^^^^^^^^^^^^^^^^^^^^^
  File "/home/airflow/.local/lib/python3.12/site-packages/airflow/operators/python.py", line 238, in execute
    return_value = self.execute_callable()
                   ^^^^^^^^^^^^^^^^^^^^^^^
  File "/home/airflow/.local/lib/python3.12/site-packages/airflow/operators/python.py", line 256, in execute_callable
    return runner.run(*self.op_args, **self.op_kwargs)
           ^^^^^^^^^^^^^^^^^^^^^^^^^^^^^^^^^^^^^^^^^^^
  File "/home/airflow/.local/lib/python3.12/site-packages/airflow/utils/operator_helpers.py", line 252, in run
    return self.func(*args, **kwargs)
           ^^^^^^^^^^^^^^^^^^^^^^^^^^
  File "/opt/airflow/dags/weather_dag.py", line 31, in run_python_script
    result = subprocess.run(['python', script_path], capture_output=True, text=True, check=True)
             ^^^^^^^^^^^^^^^^^^^^^^^^^^^^^^^^^^^^^^^^^^^^^^^^^^^^^^^^^^^^^^^^^^^^^^^^^^^^^^^^^^^
  File "/usr/local/lib/python3.12/subprocess.py", line 571, in run
    raise CalledProcessError(retcode, process.args,
subprocess.CalledProcessError: Command '['python', 'projekt_fetch2.py']' returned non-zero exit status 2.
[2024-09-03T09:07:40.086+0000] {local_task_job_runner.py:261} INFO - Task exited with return code 1
[2024-09-03T09:07:40.100+0000] {taskinstance.py:3891} INFO - 0 downstream tasks scheduled from follow-on schedule check
[2024-09-03T09:07:40.103+0000] {local_task_job_runner.py:240} INFO - ::endgroup::
