[2024-09-15T17:01:01.459+0000] {local_task_job_runner.py:120} INFO - ::group::Pre task execution logs
[2024-09-15T17:01:01.471+0000] {taskinstance.py:2076} INFO - Dependencies all met for dep_context=non-requeueable deps ti=<TaskInstance: example_python_operator_hook.upload_to_bigquery_task manual__2024-09-15T16:57:57.773618+00:00 [queued]>
[2024-09-15T17:01:01.478+0000] {taskinstance.py:2076} INFO - Dependencies all met for dep_context=requeueable deps ti=<TaskInstance: example_python_operator_hook.upload_to_bigquery_task manual__2024-09-15T16:57:57.773618+00:00 [queued]>
[2024-09-15T17:01:01.478+0000] {taskinstance.py:2306} INFO - Starting attempt 2 of 2
[2024-09-15T17:01:01.491+0000] {taskinstance.py:2330} INFO - Executing <Task(PythonOperator): upload_to_bigquery_task> on 2024-09-15 16:57:57.773618+00:00
[2024-09-15T17:01:01.498+0000] {standard_task_runner.py:90} INFO - Running: ['***', 'tasks', 'run', 'example_python_operator_hook', 'upload_to_bigquery_task', 'manual__2024-09-15T16:57:57.773618+00:00', '--job-id', '190', '--raw', '--subdir', 'DAGS_FOLDER/example_python_operator_hook.py', '--cfg-path', '/tmp/tmpuj1x_1k_']
[2024-09-15T17:01:01.499+0000] {standard_task_runner.py:91} INFO - Job 190: Subtask upload_to_bigquery_task
[2024-09-15T17:01:01.501+0000] {logging_mixin.py:188} WARNING - /home/***/.local/lib/python3.12/site-packages/***/task/task_runner/standard_task_runner.py:61 DeprecationWarning: This process (pid=541) is multi-threaded, use of fork() may lead to deadlocks in the child.
[2024-09-15T17:01:01.502+0000] {standard_task_runner.py:63} INFO - Started process 543 to run task
[2024-09-15T17:01:01.539+0000] {task_command.py:426} INFO - Running <TaskInstance: example_python_operator_hook.upload_to_bigquery_task manual__2024-09-15T16:57:57.773618+00:00 [running]> on host 81bcc4ceaa16
[2024-09-15T17:01:01.634+0000] {taskinstance.py:2648} INFO - Exporting env vars: AIRFLOW_CTX_DAG_OWNER='***' AIRFLOW_CTX_DAG_ID='example_python_operator_hook' AIRFLOW_CTX_TASK_ID='upload_to_bigquery_task' AIRFLOW_CTX_EXECUTION_DATE='2024-09-15T16:57:57.773618+00:00' AIRFLOW_CTX_TRY_NUMBER='2' AIRFLOW_CTX_DAG_RUN_ID='manual__2024-09-15T16:57:57.773618+00:00'
[2024-09-15T17:01:01.635+0000] {taskinstance.py:430} INFO - ::endgroup::
[2024-09-15T17:01:01.650+0000] {connection.py:274} WARNING - Connection schemes (type: google_cloud_platform) shall not contain '_' according to RFC3986.
[2024-09-15T17:01:01.651+0000] {base.py:84} INFO - Using connection ID 'google_cloud_defaultt' for task execution.
[2024-09-15T17:01:01.651+0000] {credentials_provider.py:353} INFO - Getting connection using `google.auth.default()` since no explicit credentials are provided.
[2024-09-15T17:01:01.653+0000] {_metadata.py:139} WARNING - Compute Engine Metadata server unavailable on attempt 1 of 3. Reason: [Errno 111] Connection refused
[2024-09-15T17:01:01.654+0000] {_metadata.py:139} WARNING - Compute Engine Metadata server unavailable on attempt 2 of 3. Reason: [Errno 111] Connection refused
[2024-09-15T17:01:01.655+0000] {_metadata.py:139} WARNING - Compute Engine Metadata server unavailable on attempt 3 of 3. Reason: [Errno 111] Connection refused
[2024-09-15T17:01:01.656+0000] {_default.py:338} WARNING - Authentication failed using Compute Engine authentication due to unavailable metadata server.
[2024-09-15T17:01:01.656+0000] {taskinstance.py:441} INFO - ::group::Post task execution logs
[2024-09-15T17:01:01.657+0000] {taskinstance.py:2905} ERROR - Task failed with exception
Traceback (most recent call last):
  File "/home/airflow/.local/lib/python3.12/site-packages/airflow/models/taskinstance.py", line 465, in _execute_task
    result = _execute_callable(context=context, **execute_callable_kwargs)
             ^^^^^^^^^^^^^^^^^^^^^^^^^^^^^^^^^^^^^^^^^^^^^^^^^^^^^^^^^^^^^
  File "/home/airflow/.local/lib/python3.12/site-packages/airflow/models/taskinstance.py", line 432, in _execute_callable
    return execute_callable(context=context, **execute_callable_kwargs)
           ^^^^^^^^^^^^^^^^^^^^^^^^^^^^^^^^^^^^^^^^^^^^^^^^^^^^^^^^^^^^
  File "/home/airflow/.local/lib/python3.12/site-packages/airflow/models/baseoperator.py", line 400, in wrapper
    return func(self, *args, **kwargs)
           ^^^^^^^^^^^^^^^^^^^^^^^^^^^
  File "/home/airflow/.local/lib/python3.12/site-packages/airflow/operators/python.py", line 235, in execute
    return_value = self.execute_callable()
                   ^^^^^^^^^^^^^^^^^^^^^^^
  File "/home/airflow/.local/lib/python3.12/site-packages/airflow/operators/python.py", line 252, in execute_callable
    return self.python_callable(*self.op_args, **self.op_kwargs)
           ^^^^^^^^^^^^^^^^^^^^^^^^^^^^^^^^^^^^^^^^^^^^^^^^^^^^^
  File "/opt/airflow/dags/example_python_operator_hook.py", line 36, in upload_to_bigquery
    client = hook.get_client()  # Get BigQuery client
             ^^^^^^^^^^^^^^^^^
  File "/home/airflow/.local/lib/python3.12/site-packages/airflow/providers/google/cloud/hooks/bigquery.py", line 211, in get_client
    credentials=self.get_credentials(),
                ^^^^^^^^^^^^^^^^^^^^^^
  File "/home/airflow/.local/lib/python3.12/site-packages/airflow/providers/google/common/hooks/base_google.py", line 308, in get_credentials
    credentials, _ = self.get_credentials_and_project_id()
                     ^^^^^^^^^^^^^^^^^^^^^^^^^^^^^^^^^^^^^
  File "/home/airflow/.local/lib/python3.12/site-packages/airflow/providers/google/common/hooks/base_google.py", line 285, in get_credentials_and_project_id
    credentials, project_id = get_credentials_and_project_id(
                              ^^^^^^^^^^^^^^^^^^^^^^^^^^^^^^^
  File "/home/airflow/.local/lib/python3.12/site-packages/airflow/providers/google/cloud/utils/credentials_provider.py", line 362, in get_credentials_and_project_id
    return _CredentialProvider(*args, **kwargs).get_credentials_and_project()
           ^^^^^^^^^^^^^^^^^^^^^^^^^^^^^^^^^^^^^^^^^^^^^^^^^^^^^^^^^^^^^^^^^^
  File "/home/airflow/.local/lib/python3.12/site-packages/airflow/providers/google/cloud/utils/credentials_provider.py", line 243, in get_credentials_and_project
    credentials, project_id = self._get_credentials_using_adc()
                              ^^^^^^^^^^^^^^^^^^^^^^^^^^^^^^^^^
  File "/home/airflow/.local/lib/python3.12/site-packages/airflow/providers/google/cloud/utils/credentials_provider.py", line 348, in _get_credentials_using_adc
    credentials, project_id = google.auth.default(scopes=self.scopes)
                              ^^^^^^^^^^^^^^^^^^^^^^^^^^^^^^^^^^^^^^^
  File "/home/airflow/.local/lib/python3.12/site-packages/google/auth/_default.py", line 691, in default
    raise exceptions.DefaultCredentialsError(_CLOUD_SDK_MISSING_CREDENTIALS)
google.auth.exceptions.DefaultCredentialsError: Your default credentials were not found. To set up Application Default Credentials, see https://cloud.google.com/docs/authentication/external/set-up-adc for more information.
[2024-09-15T17:01:01.666+0000] {taskinstance.py:1206} INFO - Marking task as FAILED. dag_id=example_python_operator_hook, task_id=upload_to_bigquery_task, run_id=manual__2024-09-15T16:57:57.773618+00:00, execution_date=20240915T165757, start_date=20240915T170101, end_date=20240915T170101
[2024-09-15T17:01:01.673+0000] {standard_task_runner.py:110} ERROR - Failed to execute job 190 for task upload_to_bigquery_task (Your default credentials were not found. To set up Application Default Credentials, see https://cloud.google.com/docs/authentication/external/set-up-adc for more information.; 543)
[2024-09-15T17:01:01.715+0000] {local_task_job_runner.py:240} INFO - Task exited with return code 1
[2024-09-15T17:01:01.726+0000] {taskinstance.py:3498} INFO - 0 downstream tasks scheduled from follow-on schedule check
[2024-09-15T17:01:01.728+0000] {local_task_job_runner.py:222} INFO - ::endgroup::
