[2024-09-12T21:55:21.083+0000] {local_task_job_runner.py:120} INFO - ::group::Pre task execution logs
[2024-09-12T21:55:21.094+0000] {taskinstance.py:2076} INFO - Dependencies all met for dep_context=non-requeueable deps ti=<TaskInstance: example_python_operator_hook.call_api_task manual__2024-09-12T21:52:17.766407+00:00 [queued]>
[2024-09-12T21:55:21.100+0000] {taskinstance.py:2076} INFO - Dependencies all met for dep_context=requeueable deps ti=<TaskInstance: example_python_operator_hook.call_api_task manual__2024-09-12T21:52:17.766407+00:00 [queued]>
[2024-09-12T21:55:21.100+0000] {taskinstance.py:2306} INFO - Starting attempt 2 of 2
[2024-09-12T21:55:21.110+0000] {taskinstance.py:2330} INFO - Executing <Task(PythonOperator): call_api_task> on 2024-09-12 21:52:17.766407+00:00
[2024-09-12T21:55:21.116+0000] {standard_task_runner.py:90} INFO - Running: ['***', 'tasks', 'run', 'example_python_operator_hook', 'call_api_task', 'manual__2024-09-12T21:52:17.766407+00:00', '--job-id', '76', '--raw', '--subdir', 'DAGS_FOLDER/example_python_operator_hook.py', '--cfg-path', '/tmp/tmpfey7qecp']
[2024-09-12T21:55:21.117+0000] {standard_task_runner.py:91} INFO - Job 76: Subtask call_api_task
[2024-09-12T21:55:21.118+0000] {logging_mixin.py:188} WARNING - /home/***/.local/lib/python3.12/site-packages/***/task/task_runner/standard_task_runner.py:61 DeprecationWarning: This process (pid=1112) is multi-threaded, use of fork() may lead to deadlocks in the child.
[2024-09-12T21:55:21.119+0000] {standard_task_runner.py:63} INFO - Started process 1114 to run task
[2024-09-12T21:55:21.145+0000] {task_command.py:426} INFO - Running <TaskInstance: example_python_operator_hook.call_api_task manual__2024-09-12T21:52:17.766407+00:00 [running]> on host 1ab47b72986b
[2024-09-12T21:55:21.204+0000] {taskinstance.py:2648} INFO - Exporting env vars: AIRFLOW_CTX_DAG_OWNER='***' AIRFLOW_CTX_DAG_ID='example_python_operator_hook' AIRFLOW_CTX_TASK_ID='call_api_task' AIRFLOW_CTX_EXECUTION_DATE='2024-09-12T21:52:17.766407+00:00' AIRFLOW_CTX_TRY_NUMBER='2' AIRFLOW_CTX_DAG_RUN_ID='manual__2024-09-12T21:52:17.766407+00:00'
[2024-09-12T21:55:21.205+0000] {taskinstance.py:430} INFO - ::endgroup::
[2024-09-12T21:55:21.221+0000] {base.py:84} INFO - Using connection ID 'ingestion_api' for task execution.
[2024-09-12T21:55:21.421+0000] {logging_mixin.py:188} INFO - DataFrame saved to PostgreSQL successfully.
[2024-09-12T21:55:21.425+0000] {connection.py:274} WARNING - Connection schemes (type: google_cloud_platform) shall not contain '_' according to RFC3986.
[2024-09-12T21:55:21.427+0000] {base.py:84} INFO - Using connection ID 'google_cloud_default' for task execution.
[2024-09-12T21:55:21.427+0000] {taskinstance.py:441} INFO - ::group::Post task execution logs
[2024-09-12T21:55:21.427+0000] {taskinstance.py:2905} ERROR - Task failed with exception
Traceback (most recent call last):
  File "/home/airflow/.local/lib/python3.12/site-packages/airflow/models/taskinstance.py", line 465, in _execute_task
    result = _execute_callable(context=context, **execute_callable_kwargs)
             ^^^^^^^^^^^^^^^^^^^^^^^^^^^^^^^^^^^^^^^^^^^^^^^^^^^^^^^^^^^^^
  File "/home/airflow/.local/lib/python3.12/site-packages/airflow/models/taskinstance.py", line 432, in _execute_callable
    return execute_callable(context=context, **execute_callable_kwargs)
           ^^^^^^^^^^^^^^^^^^^^^^^^^^^^^^^^^^^^^^^^^^^^^^^^^^^^^^^^^^^^
  File "/home/airflow/.local/lib/python3.12/site-packages/airflow/models/baseoperator.py", line 400, in wrapper
    return func(self, *args, **kwargs)
           ^^^^^^^^^^^^^^^^^^^^^^^^^^^
  File "/home/airflow/.local/lib/python3.12/site-packages/airflow/operators/python.py", line 235, in execute
    return_value = self.execute_callable()
                   ^^^^^^^^^^^^^^^^^^^^^^^
  File "/home/airflow/.local/lib/python3.12/site-packages/airflow/operators/python.py", line 252, in execute_callable
    return self.python_callable(*self.op_args, **self.op_kwargs)
           ^^^^^^^^^^^^^^^^^^^^^^^^^^^^^^^^^^^^^^^^^^^^^^^^^^^^^
  File "/opt/airflow/dags/example_python_operator_hook.py", line 42, in call_api
    upload_to_gcs(df)
  File "/opt/airflow/dags/example_python_operator_hook.py", line 50, in upload_to_gcs
    client = hook.get_conn()
             ^^^^^^^^^^^^^^^
  File "/home/airflow/.local/lib/python3.12/site-packages/airflow/providers/google/cloud/hooks/gcs.py", line 169, in get_conn
    credentials=self.get_credentials(), client_info=CLIENT_INFO, project=self.project_id
                ^^^^^^^^^^^^^^^^^^^^^^
  File "/home/airflow/.local/lib/python3.12/site-packages/airflow/providers/google/common/hooks/base_google.py", line 308, in get_credentials
    credentials, _ = self.get_credentials_and_project_id()
                     ^^^^^^^^^^^^^^^^^^^^^^^^^^^^^^^^^^^^^
  File "/home/airflow/.local/lib/python3.12/site-packages/airflow/providers/google/common/hooks/base_google.py", line 285, in get_credentials_and_project_id
    credentials, project_id = get_credentials_and_project_id(
                              ^^^^^^^^^^^^^^^^^^^^^^^^^^^^^^^
  File "/home/airflow/.local/lib/python3.12/site-packages/airflow/providers/google/cloud/utils/credentials_provider.py", line 362, in get_credentials_and_project_id
    return _CredentialProvider(*args, **kwargs).get_credentials_and_project()
           ^^^^^^^^^^^^^^^^^^^^^^^^^^^^^^^^^^^^^^^^^^^^^^^^^^^^^^^^^^^^^^^^^^
  File "/home/airflow/.local/lib/python3.12/site-packages/airflow/providers/google/cloud/utils/credentials_provider.py", line 235, in get_credentials_and_project
    credentials, project_id = self._get_credentials_using_key_path()
                              ^^^^^^^^^^^^^^^^^^^^^^^^^^^^^^^^^^^^^^
  File "/home/airflow/.local/lib/python3.12/site-packages/airflow/providers/google/cloud/utils/credentials_provider.py", line 286, in _get_credentials_using_key_path
    credentials = google.oauth2.service_account.Credentials.from_service_account_file(
                  ^^^^^^^^^^^^^^^^^^^^^^^^^^^^^^^^^^^^^^^^^^^^^^^^^^^^^^^^^^^^^^^^^^^^
  File "/home/airflow/.local/lib/python3.12/site-packages/google/oauth2/service_account.py", line 258, in from_service_account_file
    info, signer = _service_account_info.from_filename(
                   ^^^^^^^^^^^^^^^^^^^^^^^^^^^^^^^^^^^^
  File "/home/airflow/.local/lib/python3.12/site-packages/google/auth/_service_account_info.py", line 78, in from_filename
    with io.open(filename, "r", encoding="utf-8") as json_file:
         ^^^^^^^^^^^^^^^^^^^^^^^^^^^^^^^^^^^^^^^^
FileNotFoundError: [Errno 2] No such file or directory: 'C:\\Users\\diana\\Desktop\\new_test\\service-account-file.json'
[2024-09-12T21:55:21.436+0000] {taskinstance.py:1206} INFO - Marking task as FAILED. dag_id=example_python_operator_hook, task_id=call_api_task, run_id=manual__2024-09-12T21:52:17.766407+00:00, execution_date=20240912T215217, start_date=20240912T215521, end_date=20240912T215521
[2024-09-12T21:55:21.445+0000] {standard_task_runner.py:110} ERROR - Failed to execute job 76 for task call_api_task ([Errno 2] No such file or directory: 'C:\\Users\\diana\\Desktop\\new_test\\service-account-file.json'; 1114)
[2024-09-12T21:55:21.492+0000] {local_task_job_runner.py:240} INFO - Task exited with return code 1
[2024-09-12T21:55:21.503+0000] {taskinstance.py:3498} INFO - 0 downstream tasks scheduled from follow-on schedule check
[2024-09-12T21:55:21.505+0000] {local_task_job_runner.py:222} INFO - ::endgroup::
