[2024-09-12T22:39:35.365+0000] {local_task_job_runner.py:120} INFO - ::group::Pre task execution logs
[2024-09-12T22:39:35.376+0000] {taskinstance.py:2076} INFO - Dependencies all met for dep_context=non-requeueable deps ti=<TaskInstance: example_python_operator_hook.call_api_task manual__2024-09-12T22:39:34.340695+00:00 [queued]>
[2024-09-12T22:39:35.382+0000] {taskinstance.py:2076} INFO - Dependencies all met for dep_context=requeueable deps ti=<TaskInstance: example_python_operator_hook.call_api_task manual__2024-09-12T22:39:34.340695+00:00 [queued]>
[2024-09-12T22:39:35.382+0000] {taskinstance.py:2306} INFO - Starting attempt 1 of 2
[2024-09-12T22:39:35.392+0000] {taskinstance.py:2330} INFO - Executing <Task(PythonOperator): call_api_task> on 2024-09-12 22:39:34.340695+00:00
[2024-09-12T22:39:35.399+0000] {logging_mixin.py:188} WARNING - /home/***/.local/lib/python3.12/site-packages/***/task/task_runner/standard_task_runner.py:61 DeprecationWarning: This process (pid=2322) is multi-threaded, use of fork() may lead to deadlocks in the child.
[2024-09-12T22:39:35.398+0000] {standard_task_runner.py:90} INFO - Running: ['***', 'tasks', 'run', 'example_python_operator_hook', 'call_api_task', 'manual__2024-09-12T22:39:34.340695+00:00', '--job-id', '109', '--raw', '--subdir', 'DAGS_FOLDER/example_python_operator_hook.py', '--cfg-path', '/tmp/tmp2dms8h5f']
[2024-09-12T22:39:35.400+0000] {standard_task_runner.py:63} INFO - Started process 2324 to run task
[2024-09-12T22:39:35.400+0000] {standard_task_runner.py:91} INFO - Job 109: Subtask call_api_task
[2024-09-12T22:39:35.429+0000] {task_command.py:426} INFO - Running <TaskInstance: example_python_operator_hook.call_api_task manual__2024-09-12T22:39:34.340695+00:00 [running]> on host 1ab47b72986b
[2024-09-12T22:39:35.494+0000] {taskinstance.py:2648} INFO - Exporting env vars: AIRFLOW_CTX_DAG_OWNER='***' AIRFLOW_CTX_DAG_ID='example_python_operator_hook' AIRFLOW_CTX_TASK_ID='call_api_task' AIRFLOW_CTX_EXECUTION_DATE='2024-09-12T22:39:34.340695+00:00' AIRFLOW_CTX_TRY_NUMBER='1' AIRFLOW_CTX_DAG_RUN_ID='manual__2024-09-12T22:39:34.340695+00:00'
[2024-09-12T22:39:35.494+0000] {taskinstance.py:430} INFO - ::endgroup::
[2024-09-12T22:39:35.509+0000] {base.py:84} INFO - Using connection ID 'ingestion_api' for task execution.
[2024-09-12T22:39:35.705+0000] {logging_mixin.py:188} INFO - DataFrame saved to PostgreSQL successfully.
[2024-09-12T22:39:35.706+0000] {taskinstance.py:441} INFO - ::group::Post task execution logs
[2024-09-12T22:39:35.706+0000] {taskinstance.py:2905} ERROR - Task failed with exception
Traceback (most recent call last):
  File "/home/airflow/.local/lib/python3.12/site-packages/airflow/models/taskinstance.py", line 465, in _execute_task
    result = _execute_callable(context=context, **execute_callable_kwargs)
             ^^^^^^^^^^^^^^^^^^^^^^^^^^^^^^^^^^^^^^^^^^^^^^^^^^^^^^^^^^^^^
  File "/home/airflow/.local/lib/python3.12/site-packages/airflow/models/taskinstance.py", line 432, in _execute_callable
    return execute_callable(context=context, **execute_callable_kwargs)
           ^^^^^^^^^^^^^^^^^^^^^^^^^^^^^^^^^^^^^^^^^^^^^^^^^^^^^^^^^^^^
  File "/home/airflow/.local/lib/python3.12/site-packages/airflow/models/baseoperator.py", line 400, in wrapper
    return func(self, *args, **kwargs)
           ^^^^^^^^^^^^^^^^^^^^^^^^^^^
  File "/home/airflow/.local/lib/python3.12/site-packages/airflow/operators/python.py", line 235, in execute
    return_value = self.execute_callable()
                   ^^^^^^^^^^^^^^^^^^^^^^^
  File "/home/airflow/.local/lib/python3.12/site-packages/airflow/operators/python.py", line 252, in execute_callable
    return self.python_callable(*self.op_args, **self.op_kwargs)
           ^^^^^^^^^^^^^^^^^^^^^^^^^^^^^^^^^^^^^^^^^^^^^^^^^^^^^
  File "/opt/airflow/dags/example_python_operator_hook.py", line 43, in call_api
    upload_to_bigquery(df)
  File "/opt/airflow/dags/example_python_operator_hook.py", line 53, in upload_to_bigquery
    hook = BigQueryHook(bigquery_conn_id='google_cloud_default', use_legacy_sql=False)
           ^^^^^^^^^^^^^^^^^^^^^^^^^^^^^^^^^^^^^^^^^^^^^^^^^^^^^^^^^^^^^^^^^^^^^^^^^^^
  File "/home/airflow/.local/lib/python3.12/site-packages/airflow/providers/google/cloud/hooks/bigquery.py", line 159, in __init__
    super().__init__(**kwargs)
TypeError: GoogleBaseHook.__init__() got an unexpected keyword argument 'bigquery_conn_id'
[2024-09-12T22:39:35.716+0000] {taskinstance.py:1206} INFO - Marking task as UP_FOR_RETRY. dag_id=example_python_operator_hook, task_id=call_api_task, run_id=manual__2024-09-12T22:39:34.340695+00:00, execution_date=20240912T223934, start_date=20240912T223935, end_date=20240912T223935
[2024-09-12T22:39:35.726+0000] {standard_task_runner.py:110} ERROR - Failed to execute job 109 for task call_api_task (GoogleBaseHook.__init__() got an unexpected keyword argument 'bigquery_conn_id'; 2324)
[2024-09-12T22:39:35.774+0000] {local_task_job_runner.py:240} INFO - Task exited with return code 1
[2024-09-12T22:39:35.787+0000] {taskinstance.py:3498} INFO - 0 downstream tasks scheduled from follow-on schedule check
[2024-09-12T22:39:35.789+0000] {local_task_job_runner.py:222} INFO - ::endgroup::
