[2024-09-11T20:03:59.081+0000] {local_task_job_runner.py:120} INFO - ::group::Pre task execution logs
[2024-09-11T20:03:59.092+0000] {taskinstance.py:2076} INFO - Dependencies all met for dep_context=non-requeueable deps ti=<TaskInstance: example_python_operator_hook.call_api_task scheduled__2024-09-10T00:00:00+00:00 [queued]>
[2024-09-11T20:03:59.099+0000] {taskinstance.py:2076} INFO - Dependencies all met for dep_context=requeueable deps ti=<TaskInstance: example_python_operator_hook.call_api_task scheduled__2024-09-10T00:00:00+00:00 [queued]>
[2024-09-11T20:03:59.099+0000] {taskinstance.py:2306} INFO - Starting attempt 3 of 4
[2024-09-11T20:03:59.109+0000] {taskinstance.py:2330} INFO - Executing <Task(PythonOperator): call_api_task> on 2024-09-10 00:00:00+00:00
[2024-09-11T20:03:59.114+0000] {standard_task_runner.py:90} INFO - Running: ['***', 'tasks', 'run', 'example_python_operator_hook', 'call_api_task', 'scheduled__2024-09-10T00:00:00+00:00', '--job-id', '15', '--raw', '--subdir', 'DAGS_FOLDER/example_python_operator_hook.py', '--cfg-path', '/tmp/tmpp98n_bc2']
[2024-09-11T20:03:59.116+0000] {standard_task_runner.py:91} INFO - Job 15: Subtask call_api_task
[2024-09-11T20:03:59.118+0000] {logging_mixin.py:188} WARNING - /home/***/.local/lib/python3.12/site-packages/***/task/task_runner/standard_task_runner.py:61 DeprecationWarning: This process (pid=278) is multi-threaded, use of fork() may lead to deadlocks in the child.
[2024-09-11T20:03:59.118+0000] {standard_task_runner.py:63} INFO - Started process 292 to run task
[2024-09-11T20:03:59.147+0000] {task_command.py:426} INFO - Running <TaskInstance: example_python_operator_hook.call_api_task scheduled__2024-09-10T00:00:00+00:00 [running]> on host 8a8644a1e99f
[2024-09-11T20:03:59.202+0000] {taskinstance.py:2648} INFO - Exporting env vars: AIRFLOW_CTX_DAG_OWNER='***' AIRFLOW_CTX_DAG_ID='example_python_operator_hook' AIRFLOW_CTX_TASK_ID='call_api_task' AIRFLOW_CTX_EXECUTION_DATE='2024-09-10T00:00:00+00:00' AIRFLOW_CTX_TRY_NUMBER='3' AIRFLOW_CTX_DAG_RUN_ID='scheduled__2024-09-10T00:00:00+00:00'
[2024-09-11T20:03:59.203+0000] {taskinstance.py:430} INFO - ::endgroup::
[2024-09-11T20:03:59.326+0000] {base.py:84} INFO - Using connection ID 'ingestion_api' for task execution.
[2024-09-11T20:03:59.488+0000] {http.py:199} ERROR - HTTP error: Too Many Requests
[2024-09-11T20:03:59.489+0000] {http.py:200} ERROR - 
[2024-09-11T20:03:59.489+0000] {taskinstance.py:441} INFO - ::group::Post task execution logs
[2024-09-11T20:03:59.495+0000] {taskinstance.py:2905} ERROR - Task failed with exception
Traceback (most recent call last):
  File "/home/airflow/.local/lib/python3.12/site-packages/airflow/providers/http/hooks/http.py", line 197, in check_response
    response.raise_for_status()
  File "/home/airflow/.local/lib/python3.12/site-packages/requests/models.py", line 1021, in raise_for_status
    raise HTTPError(http_error_msg, response=self)
requests.exceptions.HTTPError: 429 Client Error: Too Many Requests for url: http://api.weatherbit.io/v2.0/history/daily?lat=59.33&lon=18.07&key=***&start_date=2024-09-5&end_date=2024-09-11

During handling of the above exception, another exception occurred:

Traceback (most recent call last):
  File "/home/airflow/.local/lib/python3.12/site-packages/airflow/models/taskinstance.py", line 465, in _execute_task
    result = _execute_callable(context=context, **execute_callable_kwargs)
             ^^^^^^^^^^^^^^^^^^^^^^^^^^^^^^^^^^^^^^^^^^^^^^^^^^^^^^^^^^^^^
  File "/home/airflow/.local/lib/python3.12/site-packages/airflow/models/taskinstance.py", line 432, in _execute_callable
    return execute_callable(context=context, **execute_callable_kwargs)
           ^^^^^^^^^^^^^^^^^^^^^^^^^^^^^^^^^^^^^^^^^^^^^^^^^^^^^^^^^^^^
  File "/home/airflow/.local/lib/python3.12/site-packages/airflow/models/baseoperator.py", line 400, in wrapper
    return func(self, *args, **kwargs)
           ^^^^^^^^^^^^^^^^^^^^^^^^^^^
  File "/home/airflow/.local/lib/python3.12/site-packages/airflow/operators/python.py", line 235, in execute
    return_value = self.execute_callable()
                   ^^^^^^^^^^^^^^^^^^^^^^^
  File "/home/airflow/.local/lib/python3.12/site-packages/airflow/operators/python.py", line 252, in execute_callable
    return self.python_callable(*self.op_args, **self.op_kwargs)
           ^^^^^^^^^^^^^^^^^^^^^^^^^^^^^^^^^^^^^^^^^^^^^^^^^^^^^
  File "/opt/airflow/dags/example_python_operator_hook.py", line 12, in call_api
    response = hook.run(endpoint=f'/v2.0/history/daily?lat=59.33&lon=18.07&key={api_key}&start_date=2024-09-5&end_date={end_date}')
               ^^^^^^^^^^^^^^^^^^^^^^^^^^^^^^^^^^^^^^^^^^^^^^^^^^^^^^^^^^^^^^^^^^^^^^^^^^^^^^^^^^^^^^^^^^^^^^^^^^^^^^^^^^^^^^^^^^^^
  File "/opt/airflow/plugins/hooks/ingestion_api_hook.py", line 18, in run
    response = super().run(
               ^^^^^^^^^^^^
  File "/home/airflow/.local/lib/python3.12/site-packages/airflow/providers/http/hooks/http.py", line 187, in run
    return self.run_and_check(session, prepped_request, extra_options)
           ^^^^^^^^^^^^^^^^^^^^^^^^^^^^^^^^^^^^^^^^^^^^^^^^^^^^^^^^^^^
  File "/home/airflow/.local/lib/python3.12/site-packages/airflow/providers/http/hooks/http.py", line 238, in run_and_check
    self.check_response(response)
  File "/home/airflow/.local/lib/python3.12/site-packages/airflow/providers/http/hooks/http.py", line 201, in check_response
    raise AirflowException(str(response.status_code) + ":" + response.reason)
airflow.exceptions.AirflowException: 429:Too Many Requests
[2024-09-11T20:03:59.501+0000] {taskinstance.py:1206} INFO - Marking task as UP_FOR_RETRY. dag_id=example_python_operator_hook, task_id=call_api_task, run_id=scheduled__2024-09-10T00:00:00+00:00, execution_date=20240910T000000, start_date=20240911T200359, end_date=20240911T200359
[2024-09-11T20:03:59.509+0000] {standard_task_runner.py:110} ERROR - Failed to execute job 15 for task call_api_task (429:Too Many Requests; 292)
[2024-09-11T20:03:59.532+0000] {local_task_job_runner.py:240} INFO - Task exited with return code 1
[2024-09-11T20:03:59.542+0000] {taskinstance.py:3498} INFO - 0 downstream tasks scheduled from follow-on schedule check
[2024-09-11T20:03:59.544+0000] {local_task_job_runner.py:222} INFO - ::endgroup::
[2024-09-11T20:16:52.522+0000] {local_task_job_runner.py:120} INFO - ::group::Pre task execution logs
[2024-09-11T20:16:52.536+0000] {taskinstance.py:2076} INFO - Dependencies all met for dep_context=non-requeueable deps ti=<TaskInstance: example_python_operator_hook.call_api_task scheduled__2024-09-10T00:00:00+00:00 [queued]>
[2024-09-11T20:16:52.545+0000] {taskinstance.py:2076} INFO - Dependencies all met for dep_context=requeueable deps ti=<TaskInstance: example_python_operator_hook.call_api_task scheduled__2024-09-10T00:00:00+00:00 [queued]>
[2024-09-11T20:16:52.545+0000] {taskinstance.py:2306} INFO - Starting attempt 3 of 4
[2024-09-11T20:16:52.560+0000] {taskinstance.py:2330} INFO - Executing <Task(PythonOperator): call_api_task> on 2024-09-10 00:00:00+00:00
[2024-09-11T20:16:52.567+0000] {standard_task_runner.py:90} INFO - Running: ['***', 'tasks', 'run', 'example_python_operator_hook', 'call_api_task', 'scheduled__2024-09-10T00:00:00+00:00', '--job-id', '9', '--raw', '--subdir', 'DAGS_FOLDER/example_python_operator_hook.py', '--cfg-path', '/tmp/tmpwy9joe73']
[2024-09-11T20:16:52.569+0000] {standard_task_runner.py:91} INFO - Job 9: Subtask call_api_task
[2024-09-11T20:16:52.570+0000] {logging_mixin.py:188} WARNING - /home/***/.local/lib/python3.12/site-packages/***/task/task_runner/standard_task_runner.py:61 DeprecationWarning: This process (pid=385) is multi-threaded, use of fork() may lead to deadlocks in the child.
[2024-09-11T20:16:52.571+0000] {standard_task_runner.py:63} INFO - Started process 389 to run task
[2024-09-11T20:16:52.606+0000] {task_command.py:426} INFO - Running <TaskInstance: example_python_operator_hook.call_api_task scheduled__2024-09-10T00:00:00+00:00 [running]> on host 3bade3032056
[2024-09-11T20:16:52.662+0000] {taskinstance.py:2648} INFO - Exporting env vars: AIRFLOW_CTX_DAG_OWNER='***' AIRFLOW_CTX_DAG_ID='example_python_operator_hook' AIRFLOW_CTX_TASK_ID='call_api_task' AIRFLOW_CTX_EXECUTION_DATE='2024-09-10T00:00:00+00:00' AIRFLOW_CTX_TRY_NUMBER='3' AIRFLOW_CTX_DAG_RUN_ID='scheduled__2024-09-10T00:00:00+00:00'
[2024-09-11T20:16:52.663+0000] {taskinstance.py:430} INFO - ::endgroup::
[2024-09-11T20:16:52.786+0000] {base.py:84} INFO - Using connection ID 'ingestion_api' for task execution.
[2024-09-11T20:16:53.448+0000] {http.py:199} ERROR - HTTP error: Too Many Requests
[2024-09-11T20:16:53.449+0000] {http.py:200} ERROR - 
[2024-09-11T20:16:53.449+0000] {taskinstance.py:441} INFO - ::group::Post task execution logs
[2024-09-11T20:16:53.455+0000] {taskinstance.py:2905} ERROR - Task failed with exception
Traceback (most recent call last):
  File "/home/airflow/.local/lib/python3.12/site-packages/airflow/providers/http/hooks/http.py", line 197, in check_response
    response.raise_for_status()
  File "/home/airflow/.local/lib/python3.12/site-packages/requests/models.py", line 1021, in raise_for_status
    raise HTTPError(http_error_msg, response=self)
requests.exceptions.HTTPError: 429 Client Error: Too Many Requests for url: http://api.weatherbit.io/v2.0/history/daily?lat=59.33&lon=18.07&key=***&start_date=2024-09-9&end_date=2024-09-11

During handling of the above exception, another exception occurred:

Traceback (most recent call last):
  File "/home/airflow/.local/lib/python3.12/site-packages/airflow/models/taskinstance.py", line 465, in _execute_task
    result = _execute_callable(context=context, **execute_callable_kwargs)
             ^^^^^^^^^^^^^^^^^^^^^^^^^^^^^^^^^^^^^^^^^^^^^^^^^^^^^^^^^^^^^
  File "/home/airflow/.local/lib/python3.12/site-packages/airflow/models/taskinstance.py", line 432, in _execute_callable
    return execute_callable(context=context, **execute_callable_kwargs)
           ^^^^^^^^^^^^^^^^^^^^^^^^^^^^^^^^^^^^^^^^^^^^^^^^^^^^^^^^^^^^
  File "/home/airflow/.local/lib/python3.12/site-packages/airflow/models/baseoperator.py", line 400, in wrapper
    return func(self, *args, **kwargs)
           ^^^^^^^^^^^^^^^^^^^^^^^^^^^
  File "/home/airflow/.local/lib/python3.12/site-packages/airflow/operators/python.py", line 235, in execute
    return_value = self.execute_callable()
                   ^^^^^^^^^^^^^^^^^^^^^^^
  File "/home/airflow/.local/lib/python3.12/site-packages/airflow/operators/python.py", line 252, in execute_callable
    return self.python_callable(*self.op_args, **self.op_kwargs)
           ^^^^^^^^^^^^^^^^^^^^^^^^^^^^^^^^^^^^^^^^^^^^^^^^^^^^^
  File "/opt/airflow/dags/example_python_operator_hook.py", line 12, in call_api
    response = hook.run(endpoint=f'/v2.0/history/daily?lat=59.33&lon=18.07&key={api_key}&start_date=2024-09-9&end_date={end_date}')
               ^^^^^^^^^^^^^^^^^^^^^^^^^^^^^^^^^^^^^^^^^^^^^^^^^^^^^^^^^^^^^^^^^^^^^^^^^^^^^^^^^^^^^^^^^^^^^^^^^^^^^^^^^^^^^^^^^^^^
  File "/opt/airflow/plugins/hooks/ingestion_api_hook.py", line 18, in run
    response = super().run(
               ^^^^^^^^^^^^
  File "/home/airflow/.local/lib/python3.12/site-packages/airflow/providers/http/hooks/http.py", line 187, in run
    return self.run_and_check(session, prepped_request, extra_options)
           ^^^^^^^^^^^^^^^^^^^^^^^^^^^^^^^^^^^^^^^^^^^^^^^^^^^^^^^^^^^
  File "/home/airflow/.local/lib/python3.12/site-packages/airflow/providers/http/hooks/http.py", line 238, in run_and_check
    self.check_response(response)
  File "/home/airflow/.local/lib/python3.12/site-packages/airflow/providers/http/hooks/http.py", line 201, in check_response
    raise AirflowException(str(response.status_code) + ":" + response.reason)
airflow.exceptions.AirflowException: 429:Too Many Requests
[2024-09-11T20:16:53.463+0000] {taskinstance.py:1206} INFO - Marking task as UP_FOR_RETRY. dag_id=example_python_operator_hook, task_id=call_api_task, run_id=scheduled__2024-09-10T00:00:00+00:00, execution_date=20240910T000000, start_date=20240911T201652, end_date=20240911T201653
[2024-09-11T20:16:53.471+0000] {standard_task_runner.py:110} ERROR - Failed to execute job 9 for task call_api_task (429:Too Many Requests; 389)
[2024-09-11T20:16:53.506+0000] {local_task_job_runner.py:240} INFO - Task exited with return code 1
[2024-09-11T20:16:53.517+0000] {taskinstance.py:3498} INFO - 0 downstream tasks scheduled from follow-on schedule check
[2024-09-11T20:16:53.519+0000] {local_task_job_runner.py:222} INFO - ::endgroup::
