[2024-09-12T20:46:46.434+0000] {local_task_job_runner.py:120} INFO - ::group::Pre task execution logs
[2024-09-12T20:46:46.445+0000] {taskinstance.py:2076} INFO - Dependencies all met for dep_context=non-requeueable deps ti=<TaskInstance: example_python_operator_hook.call_api_task manual__2024-09-12T20:46:45.698987+00:00 [queued]>
[2024-09-12T20:46:46.450+0000] {taskinstance.py:2076} INFO - Dependencies all met for dep_context=requeueable deps ti=<TaskInstance: example_python_operator_hook.call_api_task manual__2024-09-12T20:46:45.698987+00:00 [queued]>
[2024-09-12T20:46:46.451+0000] {taskinstance.py:2306} INFO - Starting attempt 1 of 2
[2024-09-12T20:46:46.461+0000] {taskinstance.py:2330} INFO - Executing <Task(PythonOperator): call_api_task> on 2024-09-12 20:46:45.698987+00:00
[2024-09-12T20:46:46.467+0000] {standard_task_runner.py:90} INFO - Running: ['***', 'tasks', 'run', 'example_python_operator_hook', 'call_api_task', 'manual__2024-09-12T20:46:45.698987+00:00', '--job-id', '57', '--raw', '--subdir', 'DAGS_FOLDER/example_python_operator_hook.py', '--cfg-path', '/tmp/tmpgxeblqoa']
[2024-09-12T20:46:46.469+0000] {standard_task_runner.py:91} INFO - Job 57: Subtask call_api_task
[2024-09-12T20:46:46.470+0000] {logging_mixin.py:188} WARNING - /home/***/.local/lib/python3.12/site-packages/***/task/task_runner/standard_task_runner.py:61 DeprecationWarning: This process (pid=209) is multi-threaded, use of fork() may lead to deadlocks in the child.
[2024-09-12T20:46:46.471+0000] {standard_task_runner.py:63} INFO - Started process 211 to run task
[2024-09-12T20:46:46.500+0000] {task_command.py:426} INFO - Running <TaskInstance: example_python_operator_hook.call_api_task manual__2024-09-12T20:46:45.698987+00:00 [running]> on host 58db1ee795b8
[2024-09-12T20:46:46.567+0000] {taskinstance.py:2648} INFO - Exporting env vars: AIRFLOW_CTX_DAG_OWNER='***' AIRFLOW_CTX_DAG_ID='example_python_operator_hook' AIRFLOW_CTX_TASK_ID='call_api_task' AIRFLOW_CTX_EXECUTION_DATE='2024-09-12T20:46:45.698987+00:00' AIRFLOW_CTX_TRY_NUMBER='1' AIRFLOW_CTX_DAG_RUN_ID='manual__2024-09-12T20:46:45.698987+00:00'
[2024-09-12T20:46:46.568+0000] {taskinstance.py:430} INFO - ::endgroup::
[2024-09-12T20:46:46.598+0000] {base.py:84} INFO - Using connection ID 'ingestion_api' for task execution.
[2024-09-12T20:46:46.928+0000] {logging_mixin.py:188} INFO - DataFrame saved to PostgreSQL successfully.
[2024-09-12T20:46:46.930+0000] {taskinstance.py:441} INFO - ::group::Post task execution logs
[2024-09-12T20:46:46.930+0000] {taskinstance.py:2905} ERROR - Task failed with exception
Traceback (most recent call last):
  File "/home/airflow/.local/lib/python3.12/site-packages/airflow/models/taskinstance.py", line 465, in _execute_task
    result = _execute_callable(context=context, **execute_callable_kwargs)
             ^^^^^^^^^^^^^^^^^^^^^^^^^^^^^^^^^^^^^^^^^^^^^^^^^^^^^^^^^^^^^
  File "/home/airflow/.local/lib/python3.12/site-packages/airflow/models/taskinstance.py", line 432, in _execute_callable
    return execute_callable(context=context, **execute_callable_kwargs)
           ^^^^^^^^^^^^^^^^^^^^^^^^^^^^^^^^^^^^^^^^^^^^^^^^^^^^^^^^^^^^
  File "/home/airflow/.local/lib/python3.12/site-packages/airflow/models/baseoperator.py", line 400, in wrapper
    return func(self, *args, **kwargs)
           ^^^^^^^^^^^^^^^^^^^^^^^^^^^
  File "/home/airflow/.local/lib/python3.12/site-packages/airflow/operators/python.py", line 235, in execute
    return_value = self.execute_callable()
                   ^^^^^^^^^^^^^^^^^^^^^^^
  File "/home/airflow/.local/lib/python3.12/site-packages/airflow/operators/python.py", line 252, in execute_callable
    return self.python_callable(*self.op_args, **self.op_kwargs)
           ^^^^^^^^^^^^^^^^^^^^^^^^^^^^^^^^^^^^^^^^^^^^^^^^^^^^^
  File "/opt/airflow/dags/example_python_operator_hook.py", line 40, in call_api
    upload_to_gcs(df)
  File "/opt/airflow/dags/example_python_operator_hook.py", line 46, in upload_to_gcs
    client = storage.Client()
             ^^^^^^^^^^^^^^^^
  File "/home/airflow/.local/lib/python3.12/site-packages/google/cloud/storage/client.py", line 226, in __init__
    super(Client, self).__init__(
  File "/home/airflow/.local/lib/python3.12/site-packages/google/cloud/client/__init__.py", line 320, in __init__
    _ClientProjectMixin.__init__(self, project=project, credentials=credentials)
  File "/home/airflow/.local/lib/python3.12/site-packages/google/cloud/client/__init__.py", line 268, in __init__
    project = self._determine_default(project)
              ^^^^^^^^^^^^^^^^^^^^^^^^^^^^^^^^
  File "/home/airflow/.local/lib/python3.12/site-packages/google/cloud/client/__init__.py", line 287, in _determine_default
    return _determine_default_project(project)
           ^^^^^^^^^^^^^^^^^^^^^^^^^^^^^^^^^^^
  File "/home/airflow/.local/lib/python3.12/site-packages/google/cloud/_helpers/__init__.py", line 152, in _determine_default_project
    _, project = google.auth.default()
                 ^^^^^^^^^^^^^^^^^^^^^
  File "/home/airflow/.local/lib/python3.12/site-packages/google/auth/_default.py", line 657, in default
    credentials, project_id = checker()
                              ^^^^^^^^^
  File "/home/airflow/.local/lib/python3.12/site-packages/google/auth/_default.py", line 650, in <lambda>
    lambda: _get_explicit_environ_credentials(quota_project_id=quota_project_id),
            ^^^^^^^^^^^^^^^^^^^^^^^^^^^^^^^^^^^^^^^^^^^^^^^^^^^^^^^^^^^^^^^^^^^^
  File "/home/airflow/.local/lib/python3.12/site-packages/google/auth/_default.py", line 270, in _get_explicit_environ_credentials
    credentials, project_id = load_credentials_from_file(
                              ^^^^^^^^^^^^^^^^^^^^^^^^^^^
  File "/home/airflow/.local/lib/python3.12/site-packages/google/auth/_default.py", line 114, in load_credentials_from_file
    raise exceptions.DefaultCredentialsError(
google.auth.exceptions.DefaultCredentialsError: File /opt/***/keys/service-account-file.json was not found.
[2024-09-12T20:46:46.940+0000] {taskinstance.py:1206} INFO - Marking task as UP_FOR_RETRY. dag_id=example_python_operator_hook, task_id=call_api_task, run_id=manual__2024-09-12T20:46:45.698987+00:00, execution_date=20240912T204645, start_date=20240912T204646, end_date=20240912T204646
[2024-09-12T20:46:46.948+0000] {standard_task_runner.py:110} ERROR - Failed to execute job 57 for task call_api_task (File /opt/***/keys/service-account-file.json was not found.; 211)
[2024-09-12T20:46:46.965+0000] {local_task_job_runner.py:240} INFO - Task exited with return code 1
[2024-09-12T20:46:46.976+0000] {taskinstance.py:3498} INFO - 0 downstream tasks scheduled from follow-on schedule check
[2024-09-12T20:46:46.978+0000] {local_task_job_runner.py:222} INFO - ::endgroup::
