[2024-09-03T08:44:56.911+0000] {local_task_job_runner.py:123} INFO - ::group::Pre task execution logs
[2024-09-03T08:44:56.923+0000] {taskinstance.py:2603} INFO - Dependencies all met for dep_context=non-requeueable deps ti=<TaskInstance: docker_weather_dag.run_weather_script scheduled__2024-09-02T00:00:00+00:00 [queued]>
[2024-09-03T08:44:56.930+0000] {taskinstance.py:2603} INFO - Dependencies all met for dep_context=requeueable deps ti=<TaskInstance: docker_weather_dag.run_weather_script scheduled__2024-09-02T00:00:00+00:00 [queued]>
[2024-09-03T08:44:56.930+0000] {taskinstance.py:2856} INFO - Starting attempt 1 of 2
[2024-09-03T08:44:56.940+0000] {taskinstance.py:2879} INFO - Executing <Task(DockerOperator): run_weather_script> on 2024-09-02 00:00:00+00:00
[2024-09-03T08:44:56.946+0000] {warnings.py:112} WARNING - /home/***/.local/lib/python3.12/site-packages/***/task/task_runner/standard_task_runner.py:70: DeprecationWarning: This process (pid=2290) is multi-threaded, use of fork() may lead to deadlocks in the child.
  pid = os.fork()

[2024-09-03T08:44:56.948+0000] {standard_task_runner.py:72} INFO - Started process 2294 to run task
[2024-09-03T08:44:56.947+0000] {standard_task_runner.py:104} INFO - Running: ['***', 'tasks', 'run', 'docker_weather_dag', 'run_weather_script', 'scheduled__2024-09-02T00:00:00+00:00', '--job-id', '51', '--raw', '--subdir', 'DAGS_FOLDER/docker_weather_dag.py', '--cfg-path', '/tmp/tmpkhep3_zg']
[2024-09-03T08:44:56.949+0000] {standard_task_runner.py:105} INFO - Job 51: Subtask run_weather_script
[2024-09-03T08:44:57.005+0000] {task_command.py:467} INFO - Running <TaskInstance: docker_weather_dag.run_weather_script scheduled__2024-09-02T00:00:00+00:00 [running]> on host 670a75e9450f
[2024-09-03T08:44:57.077+0000] {taskinstance.py:3122} INFO - Exporting env vars: AIRFLOW_CTX_DAG_OWNER='***' AIRFLOW_CTX_DAG_ID='docker_weather_dag' AIRFLOW_CTX_TASK_ID='run_weather_script' AIRFLOW_CTX_EXECUTION_DATE='2024-09-02T00:00:00+00:00' AIRFLOW_CTX_TRY_NUMBER='1' AIRFLOW_CTX_DAG_RUN_ID='scheduled__2024-09-02T00:00:00+00:00'
[2024-09-03T08:44:57.078+0000] {logging_mixin.py:190} INFO - Task instance is in running state
[2024-09-03T08:44:57.079+0000] {logging_mixin.py:190} INFO -  Previous state of the Task instance: queued
[2024-09-03T08:44:57.082+0000] {logging_mixin.py:190} INFO - Current task name:run_weather_script state:running start_date:2024-09-03 08:44:56.923871+00:00
[2024-09-03T08:44:57.082+0000] {logging_mixin.py:190} INFO - Dag name:docker_weather_dag and current dag run status:running
[2024-09-03T08:44:57.082+0000] {taskinstance.py:731} INFO - ::endgroup::
[2024-09-03T08:44:57.098+0000] {docker.py:157} ERROR - Failed to establish connection to Docker host unix://var/run/docker.sock: Error while fetching server API version: ('Connection aborted.', FileNotFoundError(2, 'No such file or directory'))
[2024-09-03T08:44:57.106+0000] {taskinstance.py:3301} ERROR - Task failed with exception
Traceback (most recent call last):
  File "/home/airflow/.local/lib/python3.12/site-packages/airflow/models/taskinstance.py", line 767, in _execute_task
    result = _execute_callable(context=context, **execute_callable_kwargs)
             ^^^^^^^^^^^^^^^^^^^^^^^^^^^^^^^^^^^^^^^^^^^^^^^^^^^^^^^^^^^^^
  File "/home/airflow/.local/lib/python3.12/site-packages/airflow/models/taskinstance.py", line 733, in _execute_callable
    return ExecutionCallableRunner(
           ^^^^^^^^^^^^^^^^^^^^^^^^
  File "/home/airflow/.local/lib/python3.12/site-packages/airflow/utils/operator_helpers.py", line 252, in run
    return self.func(*args, **kwargs)
           ^^^^^^^^^^^^^^^^^^^^^^^^^^
  File "/home/airflow/.local/lib/python3.12/site-packages/airflow/models/baseoperator.py", line 406, in wrapper
    return func(self, *args, **kwargs)
           ^^^^^^^^^^^^^^^^^^^^^^^^^^^
  File "/home/airflow/.local/lib/python3.12/site-packages/airflow/providers/docker/operators/docker.py", line 495, in execute
    if self.force_pull or not self.cli.images(name=self.image):
                              ^^^^^^^^
  File "/home/airflow/.local/lib/python3.12/site-packages/airflow/providers/docker/operators/docker.py", line 363, in cli
    return self.hook.api_client
           ^^^^^^^^^^^^^^^^^^^^
  File "/usr/local/lib/python3.12/functools.py", line 993, in __get__
    val = self.func(instance)
          ^^^^^^^^^^^^^^^^^^^
  File "/home/airflow/.local/lib/python3.12/site-packages/airflow/providers/docker/hooks/docker.py", line 161, in api_client
    raise AirflowException("Failed to establish connection to any given Docker hosts.")
airflow.exceptions.AirflowException: Failed to establish connection to any given Docker hosts.
[2024-09-03T08:44:57.113+0000] {logging_mixin.py:190} INFO - Task instance in failure state
[2024-09-03T08:44:57.113+0000] {logging_mixin.py:190} INFO - Task start:2024-09-03 08:44:56.923871+00:00 end:2024-09-03 08:44:57.112626+00:00 duration:0.188755
[2024-09-03T08:44:57.113+0000] {logging_mixin.py:190} INFO - Task:<Task(DockerOperator): run_weather_script> dag:<DAG: docker_weather_dag> dagrun:<DagRun docker_weather_dag @ 2024-09-02 00:00:00+00:00: scheduled__2024-09-02T00:00:00+00:00, state:running, queued_at: 2024-09-03 08:44:55.405531+00:00. externally triggered: False>
[2024-09-03T08:44:57.114+0000] {logging_mixin.py:190} INFO - Failure caused by Failed to establish connection to any given Docker hosts.
[2024-09-03T08:44:57.114+0000] {taskinstance.py:1225} INFO - Marking task as UP_FOR_RETRY. dag_id=docker_weather_dag, task_id=run_weather_script, run_id=scheduled__2024-09-02T00:00:00+00:00, execution_date=20240902T000000, start_date=20240903T084456, end_date=20240903T084457
[2024-09-03T08:44:57.125+0000] {taskinstance.py:340} INFO - ::group::Post task execution logs
[2024-09-03T08:44:57.125+0000] {standard_task_runner.py:124} ERROR - Failed to execute job 51 for task run_weather_script (Failed to establish connection to any given Docker hosts.; 2294)
Traceback (most recent call last):
  File "/home/airflow/.local/lib/python3.12/site-packages/airflow/task/task_runner/standard_task_runner.py", line 117, in _start_by_fork
    ret = args.func(args, dag=self.dag)
          ^^^^^^^^^^^^^^^^^^^^^^^^^^^^^
  File "/home/airflow/.local/lib/python3.12/site-packages/airflow/cli/cli_config.py", line 49, in command
    return func(*args, **kwargs)
           ^^^^^^^^^^^^^^^^^^^^^
  File "/home/airflow/.local/lib/python3.12/site-packages/airflow/utils/cli.py", line 115, in wrapper
    return f(*args, **kwargs)
           ^^^^^^^^^^^^^^^^^^
  File "/home/airflow/.local/lib/python3.12/site-packages/airflow/cli/commands/task_command.py", line 483, in task_run
    task_return_code = _run_task_by_selected_method(args, _dag, ti)
                       ^^^^^^^^^^^^^^^^^^^^^^^^^^^^^^^^^^^^^^^^^^^^
  File "/home/airflow/.local/lib/python3.12/site-packages/airflow/cli/commands/task_command.py", line 256, in _run_task_by_selected_method
    return _run_raw_task(args, ti)
           ^^^^^^^^^^^^^^^^^^^^^^^
  File "/home/airflow/.local/lib/python3.12/site-packages/airflow/cli/commands/task_command.py", line 341, in _run_raw_task
    return ti._run_raw_task(
           ^^^^^^^^^^^^^^^^^
  File "/home/airflow/.local/lib/python3.12/site-packages/airflow/utils/session.py", line 97, in wrapper
    return func(*args, session=session, **kwargs)
           ^^^^^^^^^^^^^^^^^^^^^^^^^^^^^^^^^^^^^^
  File "/home/airflow/.local/lib/python3.12/site-packages/airflow/models/taskinstance.py", line 2995, in _run_raw_task
    return _run_raw_task(
           ^^^^^^^^^^^^^^
  File "/home/airflow/.local/lib/python3.12/site-packages/airflow/models/taskinstance.py", line 273, in _run_raw_task
    TaskInstance._execute_task_with_callbacks(
  File "/home/airflow/.local/lib/python3.12/site-packages/airflow/models/taskinstance.py", line 3149, in _execute_task_with_callbacks
    result = self._execute_task(context, task_orig)
             ^^^^^^^^^^^^^^^^^^^^^^^^^^^^^^^^^^^^^^
  File "/home/airflow/.local/lib/python3.12/site-packages/airflow/models/taskinstance.py", line 3173, in _execute_task
    return _execute_task(self, context, task_orig)
           ^^^^^^^^^^^^^^^^^^^^^^^^^^^^^^^^^^^^^^^
  File "/home/airflow/.local/lib/python3.12/site-packages/airflow/models/taskinstance.py", line 767, in _execute_task
    result = _execute_callable(context=context, **execute_callable_kwargs)
             ^^^^^^^^^^^^^^^^^^^^^^^^^^^^^^^^^^^^^^^^^^^^^^^^^^^^^^^^^^^^^
  File "/home/airflow/.local/lib/python3.12/site-packages/airflow/models/taskinstance.py", line 733, in _execute_callable
    return ExecutionCallableRunner(
           ^^^^^^^^^^^^^^^^^^^^^^^^
  File "/home/airflow/.local/lib/python3.12/site-packages/airflow/utils/operator_helpers.py", line 252, in run
    return self.func(*args, **kwargs)
           ^^^^^^^^^^^^^^^^^^^^^^^^^^
  File "/home/airflow/.local/lib/python3.12/site-packages/airflow/models/baseoperator.py", line 406, in wrapper
    return func(self, *args, **kwargs)
           ^^^^^^^^^^^^^^^^^^^^^^^^^^^
  File "/home/airflow/.local/lib/python3.12/site-packages/airflow/providers/docker/operators/docker.py", line 495, in execute
    if self.force_pull or not self.cli.images(name=self.image):
                              ^^^^^^^^
  File "/home/airflow/.local/lib/python3.12/site-packages/airflow/providers/docker/operators/docker.py", line 363, in cli
    return self.hook.api_client
           ^^^^^^^^^^^^^^^^^^^^
  File "/usr/local/lib/python3.12/functools.py", line 993, in __get__
    val = self.func(instance)
          ^^^^^^^^^^^^^^^^^^^
  File "/home/airflow/.local/lib/python3.12/site-packages/airflow/providers/docker/hooks/docker.py", line 161, in api_client
    raise AirflowException("Failed to establish connection to any given Docker hosts.")
airflow.exceptions.AirflowException: Failed to establish connection to any given Docker hosts.
[2024-09-03T08:44:57.162+0000] {local_task_job_runner.py:261} INFO - Task exited with return code 1
[2024-09-03T08:44:57.175+0000] {taskinstance.py:3891} INFO - 0 downstream tasks scheduled from follow-on schedule check
[2024-09-03T08:44:57.178+0000] {local_task_job_runner.py:240} INFO - ::endgroup::
