[2024-09-03T07:45:57.510+0000] {local_task_job_runner.py:123} INFO - ::group::Pre task execution logs
[2024-09-03T07:45:57.524+0000] {taskinstance.py:2603} INFO - Dependencies all met for dep_context=non-requeueable deps ti=<TaskInstance: weather_data_ingestion.save_data scheduled__2024-09-02T00:00:00+00:00 [queued]>
[2024-09-03T07:45:57.530+0000] {taskinstance.py:2603} INFO - Dependencies all met for dep_context=requeueable deps ti=<TaskInstance: weather_data_ingestion.save_data scheduled__2024-09-02T00:00:00+00:00 [queued]>
[2024-09-03T07:45:57.530+0000] {taskinstance.py:2856} INFO - Starting attempt 1 of 1
[2024-09-03T07:45:57.541+0000] {taskinstance.py:2879} INFO - Executing <Task(PythonOperator): save_data> on 2024-09-02 00:00:00+00:00
[2024-09-03T07:45:57.548+0000] {warnings.py:112} WARNING - /home/***/.local/lib/python3.12/site-packages/***/task/task_runner/standard_task_runner.py:70: DeprecationWarning: This process (pid=1414) is multi-threaded, use of fork() may lead to deadlocks in the child.
  pid = os.fork()

[2024-09-03T07:45:57.549+0000] {standard_task_runner.py:72} INFO - Started process 1419 to run task
[2024-09-03T07:45:57.549+0000] {standard_task_runner.py:104} INFO - Running: ['***', 'tasks', 'run', 'weather_data_ingestion', 'save_data', 'scheduled__2024-09-02T00:00:00+00:00', '--job-id', '27', '--raw', '--subdir', 'DAGS_FOLDER/weather_dag2.py', '--cfg-path', '/tmp/tmp_gbrdz5q']
[2024-09-03T07:45:57.550+0000] {standard_task_runner.py:105} INFO - Job 27: Subtask save_data
[2024-09-03T07:45:57.590+0000] {task_command.py:467} INFO - Running <TaskInstance: weather_data_ingestion.save_data scheduled__2024-09-02T00:00:00+00:00 [running]> on host 670a75e9450f
[2024-09-03T07:45:57.671+0000] {taskinstance.py:3122} INFO - Exporting env vars: AIRFLOW_CTX_DAG_OWNER='***' AIRFLOW_CTX_DAG_ID='weather_data_ingestion' AIRFLOW_CTX_TASK_ID='save_data' AIRFLOW_CTX_EXECUTION_DATE='2024-09-02T00:00:00+00:00' AIRFLOW_CTX_TRY_NUMBER='1' AIRFLOW_CTX_DAG_RUN_ID='scheduled__2024-09-02T00:00:00+00:00'
[2024-09-03T07:45:57.673+0000] {logging_mixin.py:190} INFO - Task instance is in running state
[2024-09-03T07:45:57.673+0000] {logging_mixin.py:190} INFO -  Previous state of the Task instance: queued
[2024-09-03T07:45:57.674+0000] {logging_mixin.py:190} INFO - Current task name:save_data state:running start_date:2024-09-03 07:45:57.524698+00:00
[2024-09-03T07:45:57.674+0000] {logging_mixin.py:190} INFO - Dag name:weather_data_ingestion and current dag run status:running
[2024-09-03T07:45:57.674+0000] {taskinstance.py:731} INFO - ::endgroup::
[2024-09-03T07:45:57.675+0000] {taskinstance.py:3301} ERROR - Task failed with exception
Traceback (most recent call last):
  File "/home/airflow/.local/lib/python3.12/site-packages/airflow/models/taskinstance.py", line 767, in _execute_task
    result = _execute_callable(context=context, **execute_callable_kwargs)
             ^^^^^^^^^^^^^^^^^^^^^^^^^^^^^^^^^^^^^^^^^^^^^^^^^^^^^^^^^^^^^
  File "/home/airflow/.local/lib/python3.12/site-packages/airflow/models/taskinstance.py", line 733, in _execute_callable
    return ExecutionCallableRunner(
           ^^^^^^^^^^^^^^^^^^^^^^^^
  File "/home/airflow/.local/lib/python3.12/site-packages/airflow/utils/operator_helpers.py", line 252, in run
    return self.func(*args, **kwargs)
           ^^^^^^^^^^^^^^^^^^^^^^^^^^
  File "/home/airflow/.local/lib/python3.12/site-packages/airflow/models/baseoperator.py", line 406, in wrapper
    return func(self, *args, **kwargs)
           ^^^^^^^^^^^^^^^^^^^^^^^^^^^
  File "/home/airflow/.local/lib/python3.12/site-packages/airflow/operators/python.py", line 238, in execute
    return_value = self.execute_callable()
                   ^^^^^^^^^^^^^^^^^^^^^^^
  File "/home/airflow/.local/lib/python3.12/site-packages/airflow/operators/python.py", line 256, in execute_callable
    return runner.run(*self.op_args, **self.op_kwargs)
           ^^^^^^^^^^^^^^^^^^^^^^^^^^^^^^^^^^^^^^^^^^^
  File "/home/airflow/.local/lib/python3.12/site-packages/airflow/utils/operator_helpers.py", line 252, in run
    return self.func(*args, **kwargs)
           ^^^^^^^^^^^^^^^^^^^^^^^^^^
  File "/opt/airflow/dags/projekt_fetch2.py", line 34, in save_data_to_csv
    df = pd.DataFrame(data)
         ^^^^^^^^^^^^^^^^^^
  File "/home/airflow/.local/lib/python3.12/site-packages/pandas/core/frame.py", line 841, in __init__
    raise ValueError("DataFrame constructor not properly called!")
ValueError: DataFrame constructor not properly called!
[2024-09-03T07:45:57.687+0000] {logging_mixin.py:190} INFO - Task instance in failure state
[2024-09-03T07:45:57.687+0000] {logging_mixin.py:190} INFO - Task start:2024-09-03 07:45:57.524698+00:00 end:2024-09-03 07:45:57.686979+00:00 duration:0.162281
[2024-09-03T07:45:57.688+0000] {logging_mixin.py:190} INFO - Task:<Task(PythonOperator): save_data> dag:<DAG: weather_data_ingestion> dagrun:<DagRun weather_data_ingestion @ 2024-09-02 00:00:00+00:00: scheduled__2024-09-02T00:00:00+00:00, state:running, queued_at: 2024-09-03 07:45:54.260480+00:00. externally triggered: False>
[2024-09-03T07:45:57.688+0000] {logging_mixin.py:190} INFO - Failure caused by DataFrame constructor not properly called!
[2024-09-03T07:45:57.688+0000] {taskinstance.py:1225} INFO - Marking task as FAILED. dag_id=weather_data_ingestion, task_id=save_data, run_id=scheduled__2024-09-02T00:00:00+00:00, execution_date=20240902T000000, start_date=20240903T074557, end_date=20240903T074557
[2024-09-03T07:45:57.699+0000] {taskinstance.py:340} INFO - ::group::Post task execution logs
[2024-09-03T07:45:57.700+0000] {standard_task_runner.py:124} ERROR - Failed to execute job 27 for task save_data (DataFrame constructor not properly called!; 1419)
Traceback (most recent call last):
  File "/home/airflow/.local/lib/python3.12/site-packages/airflow/task/task_runner/standard_task_runner.py", line 117, in _start_by_fork
    ret = args.func(args, dag=self.dag)
          ^^^^^^^^^^^^^^^^^^^^^^^^^^^^^
  File "/home/airflow/.local/lib/python3.12/site-packages/airflow/cli/cli_config.py", line 49, in command
    return func(*args, **kwargs)
           ^^^^^^^^^^^^^^^^^^^^^
  File "/home/airflow/.local/lib/python3.12/site-packages/airflow/utils/cli.py", line 115, in wrapper
    return f(*args, **kwargs)
           ^^^^^^^^^^^^^^^^^^
  File "/home/airflow/.local/lib/python3.12/site-packages/airflow/cli/commands/task_command.py", line 483, in task_run
    task_return_code = _run_task_by_selected_method(args, _dag, ti)
                       ^^^^^^^^^^^^^^^^^^^^^^^^^^^^^^^^^^^^^^^^^^^^
  File "/home/airflow/.local/lib/python3.12/site-packages/airflow/cli/commands/task_command.py", line 256, in _run_task_by_selected_method
    return _run_raw_task(args, ti)
           ^^^^^^^^^^^^^^^^^^^^^^^
  File "/home/airflow/.local/lib/python3.12/site-packages/airflow/cli/commands/task_command.py", line 341, in _run_raw_task
    return ti._run_raw_task(
           ^^^^^^^^^^^^^^^^^
  File "/home/airflow/.local/lib/python3.12/site-packages/airflow/utils/session.py", line 97, in wrapper
    return func(*args, session=session, **kwargs)
           ^^^^^^^^^^^^^^^^^^^^^^^^^^^^^^^^^^^^^^
  File "/home/airflow/.local/lib/python3.12/site-packages/airflow/models/taskinstance.py", line 2995, in _run_raw_task
    return _run_raw_task(
           ^^^^^^^^^^^^^^
  File "/home/airflow/.local/lib/python3.12/site-packages/airflow/models/taskinstance.py", line 273, in _run_raw_task
    TaskInstance._execute_task_with_callbacks(
  File "/home/airflow/.local/lib/python3.12/site-packages/airflow/models/taskinstance.py", line 3149, in _execute_task_with_callbacks
    result = self._execute_task(context, task_orig)
             ^^^^^^^^^^^^^^^^^^^^^^^^^^^^^^^^^^^^^^
  File "/home/airflow/.local/lib/python3.12/site-packages/airflow/models/taskinstance.py", line 3173, in _execute_task
    return _execute_task(self, context, task_orig)
           ^^^^^^^^^^^^^^^^^^^^^^^^^^^^^^^^^^^^^^^
  File "/home/airflow/.local/lib/python3.12/site-packages/airflow/models/taskinstance.py", line 767, in _execute_task
    result = _execute_callable(context=context, **execute_callable_kwargs)
             ^^^^^^^^^^^^^^^^^^^^^^^^^^^^^^^^^^^^^^^^^^^^^^^^^^^^^^^^^^^^^
  File "/home/airflow/.local/lib/python3.12/site-packages/airflow/models/taskinstance.py", line 733, in _execute_callable
    return ExecutionCallableRunner(
           ^^^^^^^^^^^^^^^^^^^^^^^^
  File "/home/airflow/.local/lib/python3.12/site-packages/airflow/utils/operator_helpers.py", line 252, in run
    return self.func(*args, **kwargs)
           ^^^^^^^^^^^^^^^^^^^^^^^^^^
  File "/home/airflow/.local/lib/python3.12/site-packages/airflow/models/baseoperator.py", line 406, in wrapper
    return func(self, *args, **kwargs)
           ^^^^^^^^^^^^^^^^^^^^^^^^^^^
  File "/home/airflow/.local/lib/python3.12/site-packages/airflow/operators/python.py", line 238, in execute
    return_value = self.execute_callable()
                   ^^^^^^^^^^^^^^^^^^^^^^^
  File "/home/airflow/.local/lib/python3.12/site-packages/airflow/operators/python.py", line 256, in execute_callable
    return runner.run(*self.op_args, **self.op_kwargs)
           ^^^^^^^^^^^^^^^^^^^^^^^^^^^^^^^^^^^^^^^^^^^
  File "/home/airflow/.local/lib/python3.12/site-packages/airflow/utils/operator_helpers.py", line 252, in run
    return self.func(*args, **kwargs)
           ^^^^^^^^^^^^^^^^^^^^^^^^^^
  File "/opt/airflow/dags/projekt_fetch2.py", line 34, in save_data_to_csv
    df = pd.DataFrame(data)
         ^^^^^^^^^^^^^^^^^^
  File "/home/airflow/.local/lib/python3.12/site-packages/pandas/core/frame.py", line 841, in __init__
    raise ValueError("DataFrame constructor not properly called!")
ValueError: DataFrame constructor not properly called!
[2024-09-03T07:45:57.724+0000] {local_task_job_runner.py:261} INFO - Task exited with return code 1
[2024-09-03T07:45:57.736+0000] {taskinstance.py:3891} INFO - 0 downstream tasks scheduled from follow-on schedule check
[2024-09-03T07:45:57.738+0000] {local_task_job_runner.py:240} INFO - ::endgroup::
