[2024-09-15T16:43:06.952+0000] {local_task_job_runner.py:120} INFO - ::group::Pre task execution logs
[2024-09-15T16:43:06.963+0000] {taskinstance.py:2076} INFO - Dependencies all met for dep_context=non-requeueable deps ti=<TaskInstance: example_python_operator_hook.upload_to_bigquery_task manual__2024-09-15T16:43:05.882299+00:00 [queued]>
[2024-09-15T16:43:06.968+0000] {taskinstance.py:2076} INFO - Dependencies all met for dep_context=requeueable deps ti=<TaskInstance: example_python_operator_hook.upload_to_bigquery_task manual__2024-09-15T16:43:05.882299+00:00 [queued]>
[2024-09-15T16:43:06.968+0000] {taskinstance.py:2306} INFO - Starting attempt 1 of 2
[2024-09-15T16:43:06.978+0000] {taskinstance.py:2330} INFO - Executing <Task(PythonOperator): upload_to_bigquery_task> on 2024-09-15 16:43:05.882299+00:00
[2024-09-15T16:43:06.984+0000] {standard_task_runner.py:90} INFO - Running: ['***', 'tasks', 'run', 'example_python_operator_hook', 'upload_to_bigquery_task', 'manual__2024-09-15T16:43:05.882299+00:00', '--job-id', '165', '--raw', '--subdir', 'DAGS_FOLDER/example_python_operator_hook.py', '--cfg-path', '/tmp/tmplgah46ze']
[2024-09-15T16:43:06.985+0000] {standard_task_runner.py:91} INFO - Job 165: Subtask upload_to_bigquery_task
[2024-09-15T16:43:06.987+0000] {logging_mixin.py:188} WARNING - /home/***/.local/lib/python3.12/site-packages/***/task/task_runner/standard_task_runner.py:61 DeprecationWarning: This process (pid=1070) is multi-threaded, use of fork() may lead to deadlocks in the child.
[2024-09-15T16:43:06.988+0000] {standard_task_runner.py:63} INFO - Started process 1072 to run task
[2024-09-15T16:43:07.013+0000] {task_command.py:426} INFO - Running <TaskInstance: example_python_operator_hook.upload_to_bigquery_task manual__2024-09-15T16:43:05.882299+00:00 [running]> on host 9fee5f7a4be7
[2024-09-15T16:43:07.071+0000] {taskinstance.py:2648} INFO - Exporting env vars: AIRFLOW_CTX_DAG_OWNER='***' AIRFLOW_CTX_DAG_ID='example_python_operator_hook' AIRFLOW_CTX_TASK_ID='upload_to_bigquery_task' AIRFLOW_CTX_EXECUTION_DATE='2024-09-15T16:43:05.882299+00:00' AIRFLOW_CTX_TRY_NUMBER='1' AIRFLOW_CTX_DAG_RUN_ID='manual__2024-09-15T16:43:05.882299+00:00'
[2024-09-15T16:43:07.072+0000] {taskinstance.py:430} INFO - ::endgroup::
[2024-09-15T16:43:07.082+0000] {_metadata.py:139} WARNING - Compute Engine Metadata server unavailable on attempt 1 of 3. Reason: [Errno 111] Connection refused
[2024-09-15T16:43:07.083+0000] {_metadata.py:139} WARNING - Compute Engine Metadata server unavailable on attempt 2 of 3. Reason: [Errno 111] Connection refused
[2024-09-15T16:43:07.084+0000] {_metadata.py:139} WARNING - Compute Engine Metadata server unavailable on attempt 3 of 3. Reason: [Errno 111] Connection refused
[2024-09-15T16:43:07.085+0000] {_default.py:338} WARNING - Authentication failed using Compute Engine authentication due to unavailable metadata server.
[2024-09-15T16:43:07.085+0000] {taskinstance.py:441} INFO - ::group::Post task execution logs
[2024-09-15T16:43:07.085+0000] {taskinstance.py:2905} ERROR - Task failed with exception
Traceback (most recent call last):
  File "/home/airflow/.local/lib/python3.12/site-packages/airflow/models/taskinstance.py", line 465, in _execute_task
    result = _execute_callable(context=context, **execute_callable_kwargs)
             ^^^^^^^^^^^^^^^^^^^^^^^^^^^^^^^^^^^^^^^^^^^^^^^^^^^^^^^^^^^^^
  File "/home/airflow/.local/lib/python3.12/site-packages/airflow/models/taskinstance.py", line 432, in _execute_callable
    return execute_callable(context=context, **execute_callable_kwargs)
           ^^^^^^^^^^^^^^^^^^^^^^^^^^^^^^^^^^^^^^^^^^^^^^^^^^^^^^^^^^^^
  File "/home/airflow/.local/lib/python3.12/site-packages/airflow/models/baseoperator.py", line 400, in wrapper
    return func(self, *args, **kwargs)
           ^^^^^^^^^^^^^^^^^^^^^^^^^^^
  File "/home/airflow/.local/lib/python3.12/site-packages/airflow/operators/python.py", line 235, in execute
    return_value = self.execute_callable()
                   ^^^^^^^^^^^^^^^^^^^^^^^
  File "/home/airflow/.local/lib/python3.12/site-packages/airflow/operators/python.py", line 252, in execute_callable
    return self.python_callable(*self.op_args, **self.op_kwargs)
           ^^^^^^^^^^^^^^^^^^^^^^^^^^^^^^^^^^^^^^^^^^^^^^^^^^^^^
  File "/opt/airflow/dags/example_python_operator_hook.py", line 25, in upload_to_bigquery
    client = bigquery.Client(project=PROJECT_ID)
             ^^^^^^^^^^^^^^^^^^^^^^^^^^^^^^^^^^^
  File "/home/airflow/.local/lib/python3.12/site-packages/google/cloud/bigquery/client.py", line 241, in __init__
    super(Client, self).__init__(
  File "/home/airflow/.local/lib/python3.12/site-packages/google/cloud/client/__init__.py", line 321, in __init__
    Client.__init__(
  File "/home/airflow/.local/lib/python3.12/site-packages/google/cloud/client/__init__.py", line 178, in __init__
    credentials, _ = google.auth.default(scopes=scopes)
                     ^^^^^^^^^^^^^^^^^^^^^^^^^^^^^^^^^^
  File "/home/airflow/.local/lib/python3.12/site-packages/google/auth/_default.py", line 691, in default
    raise exceptions.DefaultCredentialsError(_CLOUD_SDK_MISSING_CREDENTIALS)
google.auth.exceptions.DefaultCredentialsError: Your default credentials were not found. To set up Application Default Credentials, see https://cloud.google.com/docs/authentication/external/set-up-adc for more information.
[2024-09-15T16:43:07.093+0000] {taskinstance.py:1206} INFO - Marking task as UP_FOR_RETRY. dag_id=example_python_operator_hook, task_id=upload_to_bigquery_task, run_id=manual__2024-09-15T16:43:05.882299+00:00, execution_date=20240915T164305, start_date=20240915T164306, end_date=20240915T164307
[2024-09-15T16:43:07.101+0000] {standard_task_runner.py:110} ERROR - Failed to execute job 165 for task upload_to_bigquery_task (Your default credentials were not found. To set up Application Default Credentials, see https://cloud.google.com/docs/authentication/external/set-up-adc for more information.; 1072)
[2024-09-15T16:43:07.121+0000] {local_task_job_runner.py:240} INFO - Task exited with return code 1
[2024-09-15T16:43:07.132+0000] {taskinstance.py:3498} INFO - 0 downstream tasks scheduled from follow-on schedule check
[2024-09-15T16:43:07.134+0000] {local_task_job_runner.py:222} INFO - ::endgroup::
