[2024-09-12T19:02:23.448+0000] {local_task_job_runner.py:120} INFO - ::group::Pre task execution logs
[2024-09-12T19:02:23.459+0000] {taskinstance.py:2076} INFO - Dependencies all met for dep_context=non-requeueable deps ti=<TaskInstance: example_python_operator_hook.upload_to_gcs manual__2024-09-12T19:02:20.743694+00:00 [queued]>
[2024-09-12T19:02:23.465+0000] {taskinstance.py:2076} INFO - Dependencies all met for dep_context=requeueable deps ti=<TaskInstance: example_python_operator_hook.upload_to_gcs manual__2024-09-12T19:02:20.743694+00:00 [queued]>
[2024-09-12T19:02:23.465+0000] {taskinstance.py:2306} INFO - Starting attempt 1 of 2
[2024-09-12T19:02:23.476+0000] {taskinstance.py:2330} INFO - Executing <Task(PythonOperator): upload_to_gcs> on 2024-09-12 19:02:20.743694+00:00
[2024-09-12T19:02:23.482+0000] {standard_task_runner.py:90} INFO - Running: ['***', 'tasks', 'run', 'example_python_operator_hook', 'upload_to_gcs', 'manual__2024-09-12T19:02:20.743694+00:00', '--job-id', '46', '--raw', '--subdir', 'DAGS_FOLDER/example_python_operator_hook.py', '--cfg-path', '/tmp/tmprlhsmkdf']
[2024-09-12T19:02:23.484+0000] {standard_task_runner.py:91} INFO - Job 46: Subtask upload_to_gcs
[2024-09-12T19:02:23.485+0000] {logging_mixin.py:188} WARNING - /home/***/.local/lib/python3.12/site-packages/***/task/task_runner/standard_task_runner.py:61 DeprecationWarning: This process (pid=1238) is multi-threaded, use of fork() may lead to deadlocks in the child.
[2024-09-12T19:02:23.485+0000] {standard_task_runner.py:63} INFO - Started process 1240 to run task
[2024-09-12T19:02:23.511+0000] {task_command.py:426} INFO - Running <TaskInstance: example_python_operator_hook.upload_to_gcs manual__2024-09-12T19:02:20.743694+00:00 [running]> on host 3bade3032056
[2024-09-12T19:02:23.570+0000] {taskinstance.py:2648} INFO - Exporting env vars: AIRFLOW_CTX_DAG_OWNER='***' AIRFLOW_CTX_DAG_ID='example_python_operator_hook' AIRFLOW_CTX_TASK_ID='upload_to_gcs' AIRFLOW_CTX_EXECUTION_DATE='2024-09-12T19:02:20.743694+00:00' AIRFLOW_CTX_TRY_NUMBER='1' AIRFLOW_CTX_DAG_RUN_ID='manual__2024-09-12T19:02:20.743694+00:00'
[2024-09-12T19:02:23.571+0000] {taskinstance.py:430} INFO - ::endgroup::
[2024-09-12T19:02:23.584+0000] {_metadata.py:139} WARNING - Compute Engine Metadata server unavailable on attempt 1 of 3. Reason: [Errno 111] Connection refused
[2024-09-12T19:02:23.585+0000] {_metadata.py:139} WARNING - Compute Engine Metadata server unavailable on attempt 2 of 3. Reason: [Errno 111] Connection refused
[2024-09-12T19:02:23.586+0000] {_metadata.py:139} WARNING - Compute Engine Metadata server unavailable on attempt 3 of 3. Reason: [Errno 111] Connection refused
[2024-09-12T19:02:23.586+0000] {_default.py:338} WARNING - Authentication failed using Compute Engine authentication due to unavailable metadata server.
[2024-09-12T19:02:23.587+0000] {taskinstance.py:441} INFO - ::group::Post task execution logs
[2024-09-12T19:02:23.587+0000] {taskinstance.py:2905} ERROR - Task failed with exception
Traceback (most recent call last):
  File "/home/airflow/.local/lib/python3.12/site-packages/airflow/models/taskinstance.py", line 465, in _execute_task
    result = _execute_callable(context=context, **execute_callable_kwargs)
             ^^^^^^^^^^^^^^^^^^^^^^^^^^^^^^^^^^^^^^^^^^^^^^^^^^^^^^^^^^^^^
  File "/home/airflow/.local/lib/python3.12/site-packages/airflow/models/taskinstance.py", line 432, in _execute_callable
    return execute_callable(context=context, **execute_callable_kwargs)
           ^^^^^^^^^^^^^^^^^^^^^^^^^^^^^^^^^^^^^^^^^^^^^^^^^^^^^^^^^^^^
  File "/home/airflow/.local/lib/python3.12/site-packages/airflow/models/baseoperator.py", line 400, in wrapper
    return func(self, *args, **kwargs)
           ^^^^^^^^^^^^^^^^^^^^^^^^^^^
  File "/home/airflow/.local/lib/python3.12/site-packages/airflow/operators/python.py", line 235, in execute
    return_value = self.execute_callable()
                   ^^^^^^^^^^^^^^^^^^^^^^^
  File "/home/airflow/.local/lib/python3.12/site-packages/airflow/operators/python.py", line 252, in execute_callable
    return self.python_callable(*self.op_args, **self.op_kwargs)
           ^^^^^^^^^^^^^^^^^^^^^^^^^^^^^^^^^^^^^^^^^^^^^^^^^^^^^
  File "/opt/airflow/dags/example_python_operator_hook.py", line 83, in upload_to_gcs
    client = storage.Client()
             ^^^^^^^^^^^^^^^^
  File "/home/airflow/.local/lib/python3.12/site-packages/google/cloud/storage/client.py", line 226, in __init__
    super(Client, self).__init__(
  File "/home/airflow/.local/lib/python3.12/site-packages/google/cloud/client/__init__.py", line 320, in __init__
    _ClientProjectMixin.__init__(self, project=project, credentials=credentials)
  File "/home/airflow/.local/lib/python3.12/site-packages/google/cloud/client/__init__.py", line 268, in __init__
    project = self._determine_default(project)
              ^^^^^^^^^^^^^^^^^^^^^^^^^^^^^^^^
  File "/home/airflow/.local/lib/python3.12/site-packages/google/cloud/client/__init__.py", line 287, in _determine_default
    return _determine_default_project(project)
           ^^^^^^^^^^^^^^^^^^^^^^^^^^^^^^^^^^^
  File "/home/airflow/.local/lib/python3.12/site-packages/google/cloud/_helpers/__init__.py", line 152, in _determine_default_project
    _, project = google.auth.default()
                 ^^^^^^^^^^^^^^^^^^^^^
  File "/home/airflow/.local/lib/python3.12/site-packages/google/auth/_default.py", line 691, in default
    raise exceptions.DefaultCredentialsError(_CLOUD_SDK_MISSING_CREDENTIALS)
google.auth.exceptions.DefaultCredentialsError: Your default credentials were not found. To set up Application Default Credentials, see https://cloud.google.com/docs/authentication/external/set-up-adc for more information.
[2024-09-12T19:02:23.596+0000] {taskinstance.py:1206} INFO - Marking task as UP_FOR_RETRY. dag_id=example_python_operator_hook, task_id=upload_to_gcs, run_id=manual__2024-09-12T19:02:20.743694+00:00, execution_date=20240912T190220, start_date=20240912T190223, end_date=20240912T190223
[2024-09-12T19:02:23.603+0000] {standard_task_runner.py:110} ERROR - Failed to execute job 46 for task upload_to_gcs (Your default credentials were not found. To set up Application Default Credentials, see https://cloud.google.com/docs/authentication/external/set-up-adc for more information.; 1240)
[2024-09-12T19:02:23.618+0000] {local_task_job_runner.py:240} INFO - Task exited with return code 1
[2024-09-12T19:02:23.629+0000] {taskinstance.py:3498} INFO - 0 downstream tasks scheduled from follow-on schedule check
[2024-09-12T19:02:23.631+0000] {local_task_job_runner.py:222} INFO - ::endgroup::
