[2024-09-03T07:18:03.742+0000] {local_task_job_runner.py:123} INFO - ::group::Pre task execution logs
[2024-09-03T07:18:03.754+0000] {taskinstance.py:2603} INFO - Dependencies all met for dep_context=non-requeueable deps ti=<TaskInstance: weather_dag.fetch_and_save_weather_data scheduled__2024-09-02T00:00:00+00:00 [queued]>
[2024-09-03T07:18:03.759+0000] {taskinstance.py:2603} INFO - Dependencies all met for dep_context=requeueable deps ti=<TaskInstance: weather_dag.fetch_and_save_weather_data scheduled__2024-09-02T00:00:00+00:00 [queued]>
[2024-09-03T07:18:03.760+0000] {taskinstance.py:2856} INFO - Starting attempt 1 of 2
[2024-09-03T07:18:03.770+0000] {taskinstance.py:2879} INFO - Executing <Task(PythonOperator): fetch_and_save_weather_data> on 2024-09-02 00:00:00+00:00
[2024-09-03T07:18:03.775+0000] {warnings.py:112} WARNING - /home/***/.local/lib/python3.12/site-packages/***/task/task_runner/standard_task_runner.py:70: DeprecationWarning: This process (pid=1003) is multi-threaded, use of fork() may lead to deadlocks in the child.
  pid = os.fork()

[2024-09-03T07:18:03.776+0000] {standard_task_runner.py:72} INFO - Started process 1007 to run task
[2024-09-03T07:18:03.776+0000] {standard_task_runner.py:104} INFO - Running: ['***', 'tasks', 'run', 'weather_dag', 'fetch_and_save_weather_data', 'scheduled__2024-09-02T00:00:00+00:00', '--job-id', '16', '--raw', '--subdir', 'DAGS_FOLDER/weatehr_dag.py', '--cfg-path', '/tmp/tmpgf3crzwd']
[2024-09-03T07:18:03.777+0000] {standard_task_runner.py:105} INFO - Job 16: Subtask fetch_and_save_weather_data
[2024-09-03T07:18:03.811+0000] {task_command.py:467} INFO - Running <TaskInstance: weather_dag.fetch_and_save_weather_data scheduled__2024-09-02T00:00:00+00:00 [running]> on host 670a75e9450f
[2024-09-03T07:18:03.865+0000] {taskinstance.py:3122} INFO - Exporting env vars: AIRFLOW_CTX_DAG_OWNER='***' AIRFLOW_CTX_DAG_ID='weather_dag' AIRFLOW_CTX_TASK_ID='fetch_and_save_weather_data' AIRFLOW_CTX_EXECUTION_DATE='2024-09-02T00:00:00+00:00' AIRFLOW_CTX_TRY_NUMBER='1' AIRFLOW_CTX_DAG_RUN_ID='scheduled__2024-09-02T00:00:00+00:00'
[2024-09-03T07:18:03.866+0000] {logging_mixin.py:190} INFO - Task instance is in running state
[2024-09-03T07:18:03.866+0000] {logging_mixin.py:190} INFO -  Previous state of the Task instance: queued
[2024-09-03T07:18:03.866+0000] {logging_mixin.py:190} INFO - Current task name:fetch_and_save_weather_data state:running start_date:2024-09-03 07:18:03.754729+00:00
[2024-09-03T07:18:03.867+0000] {logging_mixin.py:190} INFO - Dag name:weather_dag and current dag run status:running
[2024-09-03T07:18:03.867+0000] {taskinstance.py:731} INFO - ::endgroup::
[2024-09-03T07:18:04.219+0000] {taskinstance.py:3301} ERROR - Task failed with exception
Traceback (most recent call last):
  File "/home/airflow/.local/lib/python3.12/site-packages/airflow/models/taskinstance.py", line 767, in _execute_task
    result = _execute_callable(context=context, **execute_callable_kwargs)
             ^^^^^^^^^^^^^^^^^^^^^^^^^^^^^^^^^^^^^^^^^^^^^^^^^^^^^^^^^^^^^
  File "/home/airflow/.local/lib/python3.12/site-packages/airflow/models/taskinstance.py", line 733, in _execute_callable
    return ExecutionCallableRunner(
           ^^^^^^^^^^^^^^^^^^^^^^^^
  File "/home/airflow/.local/lib/python3.12/site-packages/airflow/utils/operator_helpers.py", line 252, in run
    return self.func(*args, **kwargs)
           ^^^^^^^^^^^^^^^^^^^^^^^^^^
  File "/home/airflow/.local/lib/python3.12/site-packages/airflow/models/baseoperator.py", line 406, in wrapper
    return func(self, *args, **kwargs)
           ^^^^^^^^^^^^^^^^^^^^^^^^^^^
  File "/home/airflow/.local/lib/python3.12/site-packages/airflow/operators/python.py", line 238, in execute
    return_value = self.execute_callable()
                   ^^^^^^^^^^^^^^^^^^^^^^^
  File "/home/airflow/.local/lib/python3.12/site-packages/airflow/operators/python.py", line 256, in execute_callable
    return runner.run(*self.op_args, **self.op_kwargs)
           ^^^^^^^^^^^^^^^^^^^^^^^^^^^^^^^^^^^^^^^^^^^
  File "/home/airflow/.local/lib/python3.12/site-packages/airflow/utils/operator_helpers.py", line 252, in run
    return self.func(*args, **kwargs)
           ^^^^^^^^^^^^^^^^^^^^^^^^^^
  File "/opt/airflow/dags/weatehr_dag.py", line 55, in fetch_and_save_weather_data
    save_data_to_csv(weather_data, output_file)
  File "/opt/airflow/dags/weatehr_dag.py", line 38, in save_data_to_csv
    df.to_csv(output_file, index=False)
  File "/home/airflow/.local/lib/python3.12/site-packages/pandas/core/generic.py", line 3902, in to_csv
    return DataFrameRenderer(formatter).to_csv(
           ^^^^^^^^^^^^^^^^^^^^^^^^^^^^^^^^^^^^
  File "/home/airflow/.local/lib/python3.12/site-packages/pandas/io/formats/format.py", line 1152, in to_csv
    csv_formatter.save()
  File "/home/airflow/.local/lib/python3.12/site-packages/pandas/io/formats/csvs.py", line 247, in save
    with get_handle(
         ^^^^^^^^^^^
  File "/home/airflow/.local/lib/python3.12/site-packages/pandas/io/common.py", line 739, in get_handle
    check_parent_directory(str(handle))
  File "/home/airflow/.local/lib/python3.12/site-packages/pandas/io/common.py", line 604, in check_parent_directory
    raise OSError(rf"Cannot save file into a non-existent directory: '{parent}'")
OSError: Cannot save file into a non-existent directory: '/path/to/your/folder'
[2024-09-03T07:18:04.233+0000] {logging_mixin.py:190} INFO - Task instance in failure state
[2024-09-03T07:18:04.233+0000] {logging_mixin.py:190} INFO - Task start:2024-09-03 07:18:03.754729+00:00 end:2024-09-03 07:18:04.232949+00:00 duration:0.47822
[2024-09-03T07:18:04.234+0000] {logging_mixin.py:190} INFO - Task:<Task(PythonOperator): fetch_and_save_weather_data> dag:<DAG: weather_dag> dagrun:<DagRun weather_dag @ 2024-09-02 00:00:00+00:00: scheduled__2024-09-02T00:00:00+00:00, state:running, queued_at: 2024-09-03 06:37:20.082036+00:00. externally triggered: False>
[2024-09-03T07:18:04.234+0000] {logging_mixin.py:190} INFO - Failure caused by Cannot save file into a non-existent directory: '/path/to/your/folder'
[2024-09-03T07:18:04.234+0000] {taskinstance.py:1225} INFO - Marking task as UP_FOR_RETRY. dag_id=weather_dag, task_id=fetch_and_save_weather_data, run_id=scheduled__2024-09-02T00:00:00+00:00, execution_date=20240902T000000, start_date=20240903T071803, end_date=20240903T071804
[2024-09-03T07:18:04.245+0000] {taskinstance.py:340} INFO - ::group::Post task execution logs
[2024-09-03T07:18:04.245+0000] {standard_task_runner.py:124} ERROR - Failed to execute job 16 for task fetch_and_save_weather_data (Cannot save file into a non-existent directory: '/path/to/your/folder'; 1007)
Traceback (most recent call last):
  File "/home/airflow/.local/lib/python3.12/site-packages/airflow/task/task_runner/standard_task_runner.py", line 117, in _start_by_fork
    ret = args.func(args, dag=self.dag)
          ^^^^^^^^^^^^^^^^^^^^^^^^^^^^^
  File "/home/airflow/.local/lib/python3.12/site-packages/airflow/cli/cli_config.py", line 49, in command
    return func(*args, **kwargs)
           ^^^^^^^^^^^^^^^^^^^^^
  File "/home/airflow/.local/lib/python3.12/site-packages/airflow/utils/cli.py", line 115, in wrapper
    return f(*args, **kwargs)
           ^^^^^^^^^^^^^^^^^^
  File "/home/airflow/.local/lib/python3.12/site-packages/airflow/cli/commands/task_command.py", line 483, in task_run
    task_return_code = _run_task_by_selected_method(args, _dag, ti)
                       ^^^^^^^^^^^^^^^^^^^^^^^^^^^^^^^^^^^^^^^^^^^^
  File "/home/airflow/.local/lib/python3.12/site-packages/airflow/cli/commands/task_command.py", line 256, in _run_task_by_selected_method
    return _run_raw_task(args, ti)
           ^^^^^^^^^^^^^^^^^^^^^^^
  File "/home/airflow/.local/lib/python3.12/site-packages/airflow/cli/commands/task_command.py", line 341, in _run_raw_task
    return ti._run_raw_task(
           ^^^^^^^^^^^^^^^^^
  File "/home/airflow/.local/lib/python3.12/site-packages/airflow/utils/session.py", line 97, in wrapper
    return func(*args, session=session, **kwargs)
           ^^^^^^^^^^^^^^^^^^^^^^^^^^^^^^^^^^^^^^
  File "/home/airflow/.local/lib/python3.12/site-packages/airflow/models/taskinstance.py", line 2995, in _run_raw_task
    return _run_raw_task(
           ^^^^^^^^^^^^^^
  File "/home/airflow/.local/lib/python3.12/site-packages/airflow/models/taskinstance.py", line 273, in _run_raw_task
    TaskInstance._execute_task_with_callbacks(
  File "/home/airflow/.local/lib/python3.12/site-packages/airflow/models/taskinstance.py", line 3149, in _execute_task_with_callbacks
    result = self._execute_task(context, task_orig)
             ^^^^^^^^^^^^^^^^^^^^^^^^^^^^^^^^^^^^^^
  File "/home/airflow/.local/lib/python3.12/site-packages/airflow/models/taskinstance.py", line 3173, in _execute_task
    return _execute_task(self, context, task_orig)
           ^^^^^^^^^^^^^^^^^^^^^^^^^^^^^^^^^^^^^^^
  File "/home/airflow/.local/lib/python3.12/site-packages/airflow/models/taskinstance.py", line 767, in _execute_task
    result = _execute_callable(context=context, **execute_callable_kwargs)
             ^^^^^^^^^^^^^^^^^^^^^^^^^^^^^^^^^^^^^^^^^^^^^^^^^^^^^^^^^^^^^
  File "/home/airflow/.local/lib/python3.12/site-packages/airflow/models/taskinstance.py", line 733, in _execute_callable
    return ExecutionCallableRunner(
           ^^^^^^^^^^^^^^^^^^^^^^^^
  File "/home/airflow/.local/lib/python3.12/site-packages/airflow/utils/operator_helpers.py", line 252, in run
    return self.func(*args, **kwargs)
           ^^^^^^^^^^^^^^^^^^^^^^^^^^
  File "/home/airflow/.local/lib/python3.12/site-packages/airflow/models/baseoperator.py", line 406, in wrapper
    return func(self, *args, **kwargs)
           ^^^^^^^^^^^^^^^^^^^^^^^^^^^
  File "/home/airflow/.local/lib/python3.12/site-packages/airflow/operators/python.py", line 238, in execute
    return_value = self.execute_callable()
                   ^^^^^^^^^^^^^^^^^^^^^^^
  File "/home/airflow/.local/lib/python3.12/site-packages/airflow/operators/python.py", line 256, in execute_callable
    return runner.run(*self.op_args, **self.op_kwargs)
           ^^^^^^^^^^^^^^^^^^^^^^^^^^^^^^^^^^^^^^^^^^^
  File "/home/airflow/.local/lib/python3.12/site-packages/airflow/utils/operator_helpers.py", line 252, in run
    return self.func(*args, **kwargs)
           ^^^^^^^^^^^^^^^^^^^^^^^^^^
  File "/opt/airflow/dags/weatehr_dag.py", line 55, in fetch_and_save_weather_data
    save_data_to_csv(weather_data, output_file)
  File "/opt/airflow/dags/weatehr_dag.py", line 38, in save_data_to_csv
    df.to_csv(output_file, index=False)
  File "/home/airflow/.local/lib/python3.12/site-packages/pandas/core/generic.py", line 3902, in to_csv
    return DataFrameRenderer(formatter).to_csv(
           ^^^^^^^^^^^^^^^^^^^^^^^^^^^^^^^^^^^^
  File "/home/airflow/.local/lib/python3.12/site-packages/pandas/io/formats/format.py", line 1152, in to_csv
    csv_formatter.save()
  File "/home/airflow/.local/lib/python3.12/site-packages/pandas/io/formats/csvs.py", line 247, in save
    with get_handle(
         ^^^^^^^^^^^
  File "/home/airflow/.local/lib/python3.12/site-packages/pandas/io/common.py", line 739, in get_handle
    check_parent_directory(str(handle))
  File "/home/airflow/.local/lib/python3.12/site-packages/pandas/io/common.py", line 604, in check_parent_directory
    raise OSError(rf"Cannot save file into a non-existent directory: '{parent}'")
OSError: Cannot save file into a non-existent directory: '/path/to/your/folder'
[2024-09-03T07:18:04.271+0000] {local_task_job_runner.py:261} INFO - Task exited with return code 1
[2024-09-03T07:18:04.283+0000] {taskinstance.py:3891} INFO - 0 downstream tasks scheduled from follow-on schedule check
[2024-09-03T07:18:04.285+0000] {local_task_job_runner.py:240} INFO - ::endgroup::
