[2024-09-12T18:28:48.607+0000] {local_task_job_runner.py:120} INFO - ::group::Pre task execution logs
[2024-09-12T18:28:48.617+0000] {taskinstance.py:2076} INFO - Dependencies all met for dep_context=non-requeueable deps ti=<TaskInstance: example_python_operator_hook.call_api_task manual__2024-09-12T18:28:47.929367+00:00 [queued]>
[2024-09-12T18:28:48.623+0000] {taskinstance.py:2076} INFO - Dependencies all met for dep_context=requeueable deps ti=<TaskInstance: example_python_operator_hook.call_api_task manual__2024-09-12T18:28:47.929367+00:00 [queued]>
[2024-09-12T18:28:48.623+0000] {taskinstance.py:2306} INFO - Starting attempt 1 of 2
[2024-09-12T18:28:48.632+0000] {taskinstance.py:2330} INFO - Executing <Task(PythonOperator): call_api_task> on 2024-09-12 18:28:47.929367+00:00
[2024-09-12T18:28:48.638+0000] {standard_task_runner.py:90} INFO - Running: ['***', 'tasks', 'run', 'example_python_operator_hook', 'call_api_task', 'manual__2024-09-12T18:28:47.929367+00:00', '--job-id', '25', '--raw', '--subdir', 'DAGS_FOLDER/example_python_operator_hook.py', '--cfg-path', '/tmp/tmpx6sx84t1']
[2024-09-12T18:28:48.640+0000] {standard_task_runner.py:91} INFO - Job 25: Subtask call_api_task
[2024-09-12T18:28:48.641+0000] {logging_mixin.py:188} WARNING - /home/***/.local/lib/python3.12/site-packages/***/task/task_runner/standard_task_runner.py:61 DeprecationWarning: This process (pid=359) is multi-threaded, use of fork() may lead to deadlocks in the child.
[2024-09-12T18:28:48.642+0000] {standard_task_runner.py:63} INFO - Started process 361 to run task
[2024-09-12T18:28:48.667+0000] {task_command.py:426} INFO - Running <TaskInstance: example_python_operator_hook.call_api_task manual__2024-09-12T18:28:47.929367+00:00 [running]> on host 3bade3032056
[2024-09-12T18:28:48.813+0000] {taskinstance.py:2648} INFO - Exporting env vars: AIRFLOW_CTX_DAG_OWNER='***' AIRFLOW_CTX_DAG_ID='example_python_operator_hook' AIRFLOW_CTX_TASK_ID='call_api_task' AIRFLOW_CTX_EXECUTION_DATE='2024-09-12T18:28:47.929367+00:00' AIRFLOW_CTX_TRY_NUMBER='1' AIRFLOW_CTX_DAG_RUN_ID='manual__2024-09-12T18:28:47.929367+00:00'
[2024-09-12T18:28:48.813+0000] {taskinstance.py:430} INFO - ::endgroup::
[2024-09-12T18:28:48.828+0000] {base.py:84} INFO - Using connection ID 'ingestion_api' for task execution.
[2024-09-12T18:28:48.992+0000] {taskinstance.py:441} INFO - ::group::Post task execution logs
[2024-09-12T18:28:48.993+0000] {taskinstance.py:2905} ERROR - Task failed with exception
Traceback (most recent call last):
  File "/home/airflow/.local/lib/python3.12/site-packages/airflow/models/taskinstance.py", line 465, in _execute_task
    result = _execute_callable(context=context, **execute_callable_kwargs)
             ^^^^^^^^^^^^^^^^^^^^^^^^^^^^^^^^^^^^^^^^^^^^^^^^^^^^^^^^^^^^^
  File "/home/airflow/.local/lib/python3.12/site-packages/airflow/models/taskinstance.py", line 432, in _execute_callable
    return execute_callable(context=context, **execute_callable_kwargs)
           ^^^^^^^^^^^^^^^^^^^^^^^^^^^^^^^^^^^^^^^^^^^^^^^^^^^^^^^^^^^^
  File "/home/airflow/.local/lib/python3.12/site-packages/airflow/models/baseoperator.py", line 400, in wrapper
    return func(self, *args, **kwargs)
           ^^^^^^^^^^^^^^^^^^^^^^^^^^^
  File "/home/airflow/.local/lib/python3.12/site-packages/airflow/operators/python.py", line 235, in execute
    return_value = self.execute_callable()
                   ^^^^^^^^^^^^^^^^^^^^^^^
  File "/home/airflow/.local/lib/python3.12/site-packages/airflow/operators/python.py", line 252, in execute_callable
    return self.python_callable(*self.op_args, **self.op_kwargs)
           ^^^^^^^^^^^^^^^^^^^^^^^^^^^^^^^^^^^^^^^^^^^^^^^^^^^^^
  File "/opt/airflow/dags/example_python_operator_hook.py", line 19, in call_api
    conn = psycopg2.connect(
           ^^^^^^^^^^^^^^^^^
  File "/home/airflow/.local/lib/python3.12/site-packages/psycopg2/__init__.py", line 122, in connect
    conn = _connect(dsn, connection_factory=connection_factory, **kwasync)
           ^^^^^^^^^^^^^^^^^^^^^^^^^^^^^^^^^^^^^^^^^^^^^^^^^^^^^^^^^^^^^^^
psycopg2.OperationalError: connection to server at "127.0.0.1", port 5432 failed: Connection refused
	Is the server running on that host and accepting TCP/IP connections?

[2024-09-12T18:28:49.000+0000] {taskinstance.py:1206} INFO - Marking task as UP_FOR_RETRY. dag_id=example_python_operator_hook, task_id=call_api_task, run_id=manual__2024-09-12T18:28:47.929367+00:00, execution_date=20240912T182847, start_date=20240912T182848, end_date=20240912T182849
[2024-09-12T18:28:49.008+0000] {standard_task_runner.py:110} ERROR - Failed to execute job 25 for task call_api_task (connection to server at "127.0.0.1", port 5432 failed: Connection refused
	Is the server running on that host and accepting TCP/IP connections?
; 361)
[2024-09-12T18:28:49.055+0000] {local_task_job_runner.py:240} INFO - Task exited with return code 1
[2024-09-12T18:28:49.066+0000] {taskinstance.py:3498} INFO - 0 downstream tasks scheduled from follow-on schedule check
[2024-09-12T18:28:49.068+0000] {local_task_job_runner.py:222} INFO - ::endgroup::
